File: Examples/data/Cr-Ni.ras
*RAS_DATA_START
*RAS_HEADER_START
*DISP_FMT_X "%.2f"
*DISP_FMT_Y "%.0f"
*DISP_FULLSCALE "2876.0000000000"
*DISP_LINE_COLOR "255.0000000000"
*DISP_LINE_STYLE "0.0000000000"
*DISP_LINE_WIDTH "0.2500000000"
*DISP_NOTE "測定データ-1"
*DISP_OFFSET_Y "0.0000000000"
*DISP_PEAKSEARCH_UNIT_Y "cps"
*DISP_RANGE_BOTTOM "0.0000000000"
*DISP_RANGE_LEFT "10.0000000000"
*DISP_RANGE_LOGCUTOFF "0.0100000000"
*DISP_RANGE_RIGHT "70.0000000000"
*DISP_RANGE_TOP "2876.0000000000"
*DISP_SCALE_MODE_Y "0.0000000000"
*DISP_TAB_NAME "2θ/θ"
*DISP_TITLE_Y "強度"
*DISP_UNIT_Y "cps"
*DISP_WINDOW_NAME "MSG_MACROENGINE"
*FILE_COMMENT " "
*FILE_MD5 ""
*FILE_MEMO " "
*FILE_OPERATOR "Administrator"
*FILE_SAMPLE " "
*FILE_TYPE "RAS_RAW"
*FILE_USERGROUP "システムマネージャ"
*FILE_VERSION "1.0000000000"
*HW_ATTACHMENT_ID "ATT1025"
*HW_ATTACHMENT_NAME "標準試料台|Standard Sample Holder"
*HW_COUNTER_ID-0 "CUT0021"
*HW_COUNTER_ID-1 "CUT0020"
*HW_COUNTER_ID-2 "CUT0020"
*HW_COUNTER_ID-3 "CMC0021"
*HW_COUNTER_NAME-0 "SC-70|SC-70"
*HW_COUNTER_NAME-1 "None|None"
*HW_COUNTER_NAME-2 "None|None"
*HW_COUNTER_NAME-3 "検出器モノクロメータ|Detector monochromator"
*HW_COUNTER_SELECT_NAME "SC-70|SC-70"
*HW_ECP_HV "641.5000000000"
*HW_ECP_HV_UNIT "V"
*HW_GONIOMETER_ID "GON0070"
*HW_GONIOMETER_NAME "MiniFlex 300/600|MiniFlex 300/600"
*HW_GONIOMETER_RADIUS-0 "79.0"
*HW_GONIOMETER_RADIUS-1 "91.5"
*HW_GONIOMETER_RADIUS-2 "150.0"
*HW_GONIOMETER_RADIUS-3 "0"
*HW_GONIOMETER_RADIUS-4 "103.4"
*HW_GONIOMETER_RADIUS-5 "150.0"
*HW_GONIOMETER_RADIUS-6 "46.6"
*HW_GONIOMETER_RADIUS-7 "160.0"
*HW_I_OPT_ID-0 "ISL0021"
*HW_I_OPT_ID-1 "ISO0021"
*HW_I_OPT_NAME-0 "発散スリット|Divergence slit"
*HW_I_OPT_NAME-1 "入射平行スリット|Incident parallel slit"
*HW_R_ATTENUATER_AUTOMODE "0"
*HW_R_OPT_ID-0 "RSS0021"
*HW_R_OPT_ID-1 "RSO0021"
*HW_R_OPT_ID-2 "RRS0021"
*HW_R_OPT_NAME-0 "散乱スリット|Scattering slit"
*HW_R_OPT_NAME-1 "受光平行スリット|Receiving soller slit"
*HW_R_OPT_NAME-2 "受光スリット|Receiving slit"
*HW_SAMPLE_HOLDER_ID "SMP0000"
*HW_SAMPLE_HOLDER_NAME "無し|None"
*HW_XG_CURRENT_MAX "15"
*HW_XG_CURRENT_MIN "2"
*HW_XG_CURRENT_RESOLUTION "1"
*HW_XG_CURRENT_UNIT "mA"
*HW_XG_FOCUS "1mm x 10mm"
*HW_XG_FOCUS_TYPE "Normal"
*HW_XG_ID ""
*HW_XG_NAME "300W/600W 封入管-A|300W/600W Sealed tube-A"
*HW_XG_TARGET_ATOMIC_NUMBER "29.0000000000"
*HW_XG_TARGET_NAME "Cu"
*HW_XG_TYPE "Hermetic"
*HW_XG_VOLTAGE_MAX "40"
*HW_XG_VOLTAGE_MIN "20"
*HW_XG_VOLTAGE_RESOLUTION "1"
*HW_XG_VOLTAGE_UNIT "kV"
*HW_XG_WATT_MAX "1"
*HW_XG_WATT_UNIT "kW"
*HW_XG_WAVE_LENGTH_ALPHA1 "1.540593"
*HW_XG_WAVE_LENGTH_ALPHA2 "1.544414"
*HW_XG_WAVE_LENGTH_BETA "1.392250"
*MEAS_COND_AXIS_NAME-0 "2θ/θ"
*MEAS_COND_AXIS_NAME-1 "Soller(inc.)"
*MEAS_COND_AXIS_NAME-2 "IHS"
*MEAS_COND_AXIS_NAME-3 "DS"
*MEAS_COND_AXIS_NAME-4 "SS"
*MEAS_COND_AXIS_NAME-5 "Soller(rec.)"
*MEAS_COND_AXIS_NAME-6 "RS"
*MEAS_COND_AXIS_NAME-7 "フィルター"
*MEAS_COND_AXIS_NAME-8 "モノクロメータ"
*MEAS_COND_AXIS_NAME-9 "HV"
*MEAS_COND_AXIS_NAME-10 "PHA"
*MEAS_COND_AXIS_NAME_INTERNAL-0 "TwoThetaTheta"
*MEAS_COND_AXIS_NAME_INTERNAL-1 "IncidentSollerSlit"
*MEAS_COND_AXIS_NAME_INTERNAL-2 "IncidentAxdSlit"
*MEAS_COND_AXIS_NAME_INTERNAL-3 "IncidentSlitBox"
*MEAS_COND_AXIS_NAME_INTERNAL-4 "ReceivingSlitBox1"
*MEAS_COND_AXIS_NAME_INTERNAL-5 "ReceivingSollerSlit"
*MEAS_COND_AXIS_NAME_INTERNAL-6 "ReceivingSlitBox2"
*MEAS_COND_AXIS_NAME_INTERNAL-7 "Filter"
*MEAS_COND_AXIS_NAME_INTERNAL-8 "CounterMonochromator"
*MEAS_COND_AXIS_NAME_INTERNAL-9 "HV"
*MEAS_COND_AXIS_NAME_INTERNAL-10 "PHA"
*MEAS_COND_AXIS_NAME_MAGICNO-0 "268632064.0000000000"
*MEAS_COND_AXIS_NAME_MAGICNO-1 "20971521.0000000000"
*MEAS_COND_AXIS_NAME_MAGICNO-2 "22020097.0000000000"
*MEAS_COND_AXIS_NAME_MAGICNO-3 "22020097.0000000000"
*MEAS_COND_AXIS_NAME_MAGICNO-4 "23068673.0000000000"
*MEAS_COND_AXIS_NAME_MAGICNO-5 "20971521.0000000000"
*MEAS_COND_AXIS_NAME_MAGICNO-6 "23068673.0000000000"
*MEAS_COND_AXIS_NAME_MAGICNO-7 "20971521.0000000000"
*MEAS_COND_AXIS_NAME_MAGICNO-8 "20971521.0000000000"
*MEAS_COND_AXIS_NAME_MAGICNO-9 "0.0000000000"
*MEAS_COND_AXIS_NAME_MAGICNO-10 "0.0000000000"
*MEAS_COND_AXIS_OFFSET-0 "0.0000000000"
*MEAS_COND_AXIS_OFFSET-1 "-"
*MEAS_COND_AXIS_OFFSET-2 "-"
*MEAS_COND_AXIS_OFFSET-3 "-"
*MEAS_COND_AXIS_OFFSET-4 "-"
*MEAS_COND_AXIS_OFFSET-5 "-"
*MEAS_COND_AXIS_OFFSET-6 "-"
*MEAS_COND_AXIS_OFFSET-7 "-"
*MEAS_COND_AXIS_OFFSET-8 "-"
*MEAS_COND_AXIS_OFFSET-9 "-"
*MEAS_COND_AXIS_OFFSET-10 "-"
*MEAS_COND_AXIS_POSITION-0 "10.0000000000"
*MEAS_COND_AXIS_POSITION-1 "5.0deg"
*MEAS_COND_AXIS_POSITION-2 "10.0mm"
*MEAS_COND_AXIS_POSITION-3 "1.250deg"
*MEAS_COND_AXIS_POSITION-4 "1.250deg"
*MEAS_COND_AXIS_POSITION-5 "5.0deg"
*MEAS_COND_AXIS_POSITION-6 "0.3mm"
*MEAS_COND_AXIS_POSITION-7 "None"
*MEAS_COND_AXIS_POSITION-8 "Bent"
*MEAS_COND_AXIS_POSITION-9 "641.5000000000"
*MEAS_COND_AXIS_POSITION-10 "566.2500000000"
*MEAS_COND_AXIS_UNIT-0 "deg"
*MEAS_COND_AXIS_UNIT-1 ""
*MEAS_COND_AXIS_UNIT-2 ""
*MEAS_COND_AXIS_UNIT-3 ""
*MEAS_COND_AXIS_UNIT-4 ""
*MEAS_COND_AXIS_UNIT-5 ""
*MEAS_COND_AXIS_UNIT-6 ""
*MEAS_COND_AXIS_UNIT-7 ""
*MEAS_COND_AXIS_UNIT-8 ""
*MEAS_COND_AXIS_UNIT-9 "V"
*MEAS_COND_AXIS_UNIT-10 "mV"
*MEAS_COND_COUNTER_CNTLOSS_CORR "0.0000000000"
*MEAS_COND_COUNTER_PHABASE "566.2500000000"
*MEAS_COND_COUNTER_PHAWINDOW "878.7500000000"
*MEAS_COND_COUNTER_PHA_UNIT "mV"
*MEAS_COND_COUNTER_TAUDIFF "0.2500000000"
*MEAS_COND_COUNTER_TAUINT "0.7500000000"
*MEAS_COND_IRRADIATION_MODE "OFF"
*MEAS_COND_IRRADIATION_WIDTH ""
*MEAS_COND_OPT_ATTR " "
*MEAS_COND_OPT_NAME ""
*MEAS_COND_UNSYMMETRIC_MODE "OFF"
*MEAS_COND_XG_CURRENT "15.0000000000"
*MEAS_COND_XG_VOLTAGE "40.0000000000"
*MEAS_COND_XG_WAVE_TYPE "Ka"
*MEAS_DATA_COUNT "3001.0000000000"
*MEAS_SCAN_AXIS_X "2θ/θ"
*MEAS_SCAN_AXIS_X_INTERNAL "TwoThetaTheta"
*MEAS_SCAN_END_TIME "11/05/20 18:14:35"
*MEAS_SCAN_MODE "CONTINUOUS"
*MEAS_SCAN_MONITOR "0"
*MEAS_SCAN_RESOLUTION_X "0.0025"
*MEAS_SCAN_SPEED "2.0000"
*MEAS_SCAN_SPEED_UNIT "deg/min"
*MEAS_SCAN_START "10.0000000000"
*MEAS_SCAN_START_TIME "11/05/20 17:44:25"
*MEAS_SCAN_STEP "0.0200000000"
*MEAS_SCAN_STOP "70.0000000000"
*MEAS_SCAN_UNIT_X "deg"
*MEAS_SCAN_UNIT_Y "counts"
*SLIT_SYSTEM "0"
*RAS_HEADER_END
*RAS_INT_START
10.0000 26.0000 1.0000
10.0600 14.0000 1.0000
10.1200 25.0000 1.0000
10.1800 27.0000 1.0000
10.2400 12.0000 1.0000
10.3000 31.0000 1.0000
10.3600 13.0000 1.0000
10.4200 23.0000 1.0000
10.4800 16.0000 1.0000
10.5400 11.0000 1.0000
10.6000 17.0000 1.0000
10.6600 16.0000 1.0000
10.7200 16.0000 1.0000
10.7800 21.0000 1.0000
10.8400 16.0000 1.0000
10.9000 18.0000 1.0000
10.9600 22.0000 1.0000
11.0200 20.0000 1.0000
11.0800 25.0000 1.0000
11.1400 20.0000 1.0000
11.2000 22.0000 1.0000
11.2600 17.0000 1.0000
11.3200 18.0000 1.0000
11.3800 23.0000 1.0000
11.4400 23.0000 1.0000
11.5000 33.0000 1.0000
11.5600 18.0000 1.0000
11.6200 15.0000 1.0000
11.6800 21.0000 1.0000
11.7400 16.0000 1.0000
11.8000 19.0000 1.0000
11.8600 29.0000 1.0000
11.9200 24.0000 1.0000
11.9800 20.0000 1.0000
12.0400 16.0000 1.0000
12.1000 21.0000 1.0000
12.1600 20.0000 1.0000
12.2200 27.0000 1.0000
12.2800 16.0000 1.0000
12.3400 24.0000 1.0000
12.4000 17.0000 1.0000
12.4600 16.0000 1.0000
12.5200 28.0000 1.0000
12.5800 13.0000 1.0000
12.6400 24.0000 1.0000
12.7000 17.0000 1.0000
12.7600 23.0000 1.0000
12.8200 17.0000 1.0000
12.8800 20.0000 1.0000
12.9400 28.0000 1.0000
13.0000 16.0000 1.0000
13.0600 17.0000 1.0000
13.1200 26.0000 1.0000
13.1800 24.0000 1.0000
13.2400 15.0000 1.0000
13.3000 12.0000 1.0000
13.3600 11.0000 1.0000
13.4200 15.0000 1.0000
13.4800 18.0000 1.0000
13.5400 26.0000 1.0000
13.6000 23.0000 1.0000
13.6600 25.0000 1.0000
13.7200 24.0000 1.0000
13.7800 27.0000 1.0000
13.8400 23.0000 1.0000
13.9000 23.0000 1.0000
13.9600 21.0000 1.0000
14.0200 15.0000 1.0000
14.0800 24.0000 1.0000
14.1400 21.0000 1.0000
14.2000 23.0000 1.0000
14.2600 25.0000 1.0000
14.3200 26.0000 1.0000
14.3800 18.0000 1.0000
14.4400 21.0000 1.0000
14.5000 22.0000 1.0000
14.5600 20.0000 1.0000
14.6200 20.0000 1.0000
14.6800 29.0000 1.0000
14.7400 30.0000 1.0000
14.8000 18.0000 1.0000
14.8600 27.0000 1.0000
14.9200 20.0000 1.0000
14.9800 26.0000 1.0000
15.0400 23.0000 1.0000
15.1000 15.0000 1.0000
15.1600 28.0000 1.0000
15.2200 23.0000 1.0000
15.2800 21.0000 1.0000
15.3400 25.0000 1.0000
15.4000 18.0000 1.0000
15.4600 25.0000 1.0000
15.5200 18.0000 1.0000
15.5800 26.0000 1.0000
15.6400 27.0000 1.0000
15.7000 25.0000 1.0000
15.7600 36.0000 1.0000
15.8200 28.0000 1.0000
15.8800 36.0000 1.0000
15.9400 30.0000 1.0000
16.0000 31.0000 1.0000
16.0600 22.0000 1.0000
16.1200 32.0000 1.0000
16.1800 20.0000 1.0000
16.2400 23.0000 1.0000
16.3000 30.0000 1.0000
16.3600 29.0000 1.0000
16.4200 28.0000 1.0000
16.4800 26.0000 1.0000
16.5400 21.0000 1.0000
16.6000 29.0000 1.0000
16.6600 31.0000 1.0000
16.7200 30.0000 1.0000
16.7800 25.0000 1.0000
16.8400 30.0000 1.0000
16.9000 24.0000 1.0000
16.9600 32.0000 1.0000
17.0200 30.0000 1.0000
17.0800 30.0000 1.0000
17.1400 38.0000 1.0000
17.2000 30.0000 1.0000
17.2600 36.0000 1.0000
17.3200 27.0000 1.0000
17.3800 24.0000 1.0000
17.4400 26.0000 1.0000
17.5000 26.0000 1.0000
17.5600 24.0000 1.0000
17.6200 23.0000 1.0000
17.6800 28.0000 1.0000
17.7400 38.0000 1.0000
17.8000 29.0000 1.0000
17.8600 28.0000 1.0000
17.9200 30.0000 1.0000
17.9800 32.0000 1.0000
18.0400 36.0000 1.0000
18.1000 39.0000 1.0000
18.1600 31.0000 1.0000
18.2200 32.0000 1.0000
18.2800 43.0000 1.0000
18.3400 29.0000 1.0000
18.4000 28.0000 1.0000
18.4600 44.0000 1.0000
18.5200 36.0000 1.0000
18.5800 27.0000 1.0000
18.6400 29.0000 1.0000
18.7000 28.0000 1.0000
18.7600 33.0000 1.0000
18.8200 49.0000 1.0000
18.8800 28.0000 1.0000
18.9400 24.0000 1.0000
19.0000 32.0000 1.0000
19.0600 32.0000 1.0000
19.1200 34.0000 1.0000
19.1800 45.0000 1.0000
19.2400 40.0000 1.0000
19.3000 34.0000 1.0000
19.3600 23.0000 1.0000
19.4200 37.0000 1.0000
19.4800 33.0000 1.0000
19.5400 32.0000 1.0000
19.6000 29.0000 1.0000
19.6600 35.0000 1.0000
19.7200 29.0000 1.0000
19.7800 35.0000 1.0000
19.8400 48.0000 1.0000
19.9000 31.0000 1.0000
19.9600 31.0000 1.0000
20.0200 26.0000 1.0000
20.0800 38.0000 1.0000
20.1400 25.0000 1.0000
20.2000 44.0000 1.0000
20.2600 40.0000 1.0000
20.3200 31.0000 1.0000
20.3800 41.0000 1.0000
20.4400 30.0000 1.0000
20.5000 41.0000 1.0000
20.5600 30.0000 1.0000
20.6200 37.0000 1.0000
20.6800 24.0000 1.0000
20.7400 27.0000 1.0000
20.8000 39.0000 1.0000
20.8600 45.0000 1.0000
20.9200 33.0000 1.0000
20.9800 44.0000 1.0000
21.0400 30.0000 1.0000
21.1000 37.0000 1.0000
21.1600 30.0000 1.0000
21.2200 45.0000 1.0000
21.2800 32.0000 1.0000
21.3400 35.0000 1.0000
21.4000 36.0000 1.0000
21.4600 38.0000 1.0000
21.5200 27.0000 1.0000
21.5800 35.0000 1.0000
21.6400 47.0000 1.0000
21.7000 30.0000 1.0000
21.7600 31.0000 1.0000
21.8200 22.0000 1.0000
21.8800 39.0000 1.0000
21.9400 33.0000 1.0000
22.0000 29.0000 1.0000
22.0600 31.0000 1.0000
22.1200 26.0000 1.0000
22.1800 31.0000 1.0000
22.2400 29.0000 1.0000
22.3000 33.0000 1.0000
22.3600 29.0000 1.0000
22.4200 24.0000 1.0000
22.4800 36.0000 1.0000
22.5400 34.0000 1.0000
22.6000 36.0000 1.0000
22.6600 24.0000 1.0000
22.7200 24.0000 1.0000
22.7800 29.0000 1.0000
22.8400 30.0000 1.0000
22.9000 26.0000 1.0000
22.9600 28.0000 1.0000
23.0200 31.0000 1.0000
23.0800 29.0000 1.0000
23.1400 27.0000 1.0000
23.2000 33.0000 1.0000
23.2600 36.0000 1.0000
23.3200 22.0000 1.0000
23.3800 25.0000 1.0000
23.4400 25.0000 1.0000
23.5000 25.0000 1.0000
23.5600 29.0000 1.0000
23.6200 23.0000 1.0000
23.6800 35.0000 1.0000
23.7400 23.0000 1.0000
23.8000 28.0000 1.0000
23.8600 34.0000 1.0000
23.9200 27.0000 1.0000
23.9800 34.0000 1.0000
24.0400 30.0000 1.0000
24.1000 30.0000 1.0000
24.1600 34.0000 1.0000
24.2200 22.0000 1.0000
24.2800 27.0000 1.0000
24.3400 24.0000 1.0000
24.4000 22.0000 1.0000
24.4600 29.0000 1.0000
24.5200 34.0000 1.0000
24.5800 29.0000 1.0000
24.6400 27.0000 1.0000
24.7000 19.0000 1.0000
24.7600 29.0000 1.0000
24.8200 23.0000 1.0000
24.8800 23.0000 1.0000
24.9400 23.0000 1.0000
25.0000 31.0000 1.0000
25.0600 19.0000 1.0000
25.1200 23.0000 1.0000
25.1800 26.0000 1.0000
25.2400 29.0000 1.0000
25.3000 22.0000 1.0000
25.3600 25.0000 1.0000
25.4200 25.0000 1.0000
25.4800 15.0000 1.0000
25.5400 24.0000 1.0000
25.6000 18.0000 1.0000
25.6600 23.0000 1.0000
25.7200 23.0000 1.0000
25.7800 20.0000 1.0000
25.8400 21.0000 1.0000
25.9000 22.0000 1.0000
25.9600 23.0000 1.0000
26.0200 20.0000 1.0000
26.0800 17.0000 1.0000
26.1400 18.0000 1.0000
26.2000 17.0000 1.0000
26.2600 15.0000 1.0000
26.3200 18.0000 1.0000
26.3800 25.0000 1.0000
26.4400 12.0000 1.0000
26.5000 23.0000 1.0000
26.5600 20.0000 1.0000
26.6200 16.0000 1.0000
26.6800 25.0000 1.0000
26.7400 22.0000 1.0000
26.8000 31.0000 1.0000
26.8600 20.0000 1.0000
26.9200 19.0000 1.0000
26.9800 25.0000 1.0000
27.0400 18.0000 1.0000
27.1000 13.0000 1.0000
27.1600 20.0000 1.0000
27.2200 11.0000 1.0000
27.2800 18.0000 1.0000
27.3400 13.0000 1.0000
27.4000 16.0000 1.0000
27.4600 19.0000 1.0000
27.5200 18.0000 1.0000
27.5800 17.0000 1.0000
27.6400 24.0000 1.0000
27.7000 20.0000 1.0000
27.7600 19.0000 1.0000
27.8200 17.0000 1.0000
27.8800 25.0000 1.0000
27.9400 18.0000 1.0000
28.0000 21.0000 1.0000
28.0600 18.0000 1.0000
28.1200 21.0000 1.0000
28.1800 15.0000 1.0000
28.2400 14.0000 1.0000
28.3000 18.0000 1.0000
28.3600 11.0000 1.0000
28.4200 17.0000 1.0000
28.4800 17.0000 1.0000
28.5400 26.0000 1.0000
28.6000 23.0000 1.0000
28.6600 14.0000 1.0000
28.7200 20.0000 1.0000
28.7800 15.0000 1.0000
28.8400 12.0000 1.0000
28.9000 23.0000 1.0000
28.9600 16.0000 1.0000
29.0200 20.0000 1.0000
29.0800 13.0000 1.0000
29.1400 10.0000 1.0000
29.2000 21.0000 1.0000
29.2600 13.0000 1.0000
29.3200 10.0000 1.0000
29.3800 14.0000 1.0000
29.4400 19.0000 1.0000
29.5000 20.0000 1.0000
29.5600 14.0000 1.0000
29.6200 17.0000 1.0000
29.6800 19.0000 1.0000
29.7400 18.0000 1.0000
29.8000 15.0000 1.0000
29.8600 11.0000 1.0000
29.9200 12.0000 1.0000
29.9800 11.0000 1.0000
30.0400 17.0000 1.0000
30.1000 17.0000 1.0000
30.1600 14.0000 1.0000
30.2200 11.0000 1.0000
30.2800 9.0000 1.0000
30.3400 13.0000 1.0000
30.4000 19.0000 1.0000
30.4600 8.0000 1.0000
30.5200 24.0000 1.0000
30.5800 8.0000 1.0000
30.6400 14.0000 1.0000
30.7000 16.0000 1.0000
30.7600 19.0000 1.0000
30.8200 20.0000 1.0000
30.8800 14.0000 1.0000
30.9400 13.0000 1.0000
31.0000 16.0000 1.0000
31.0600 10.0000 1.0000
31.1200 18.0000 1.0000
31.1800 13.0000 1.0000
31.2400 12.0000 1.0000
31.3000 14.0000 1.0000
31.3600 14.0000 1.0000
31.4200 14.0000 1.0000
31.4800 13.0000 1.0000
31.5400 15.0000 1.0000
31.6000 20.0000 1.0000
31.6600 10.0000 1.0000
31.7200 12.0000 1.0000
31.7800 16.0000 1.0000
31.8400 9.0000 1.0000
31.9000 16.0000 1.0000
31.9600 10.0000 1.0000
32.0200 12.0000 1.0000
32.0800 22.0000 1.0000
32.1400 9.0000 1.0000
32.2000 16.0000 1.0000
32.2600 12.0000 1.0000
32.3200 17.0000 1.0000
32.3800 10.0000 1.0000
32.4400 12.0000 1.0000
32.5000 16.0000 1.0000
32.5600 14.0000 1.0000
32.6200 12.0000 1.0000
32.6800 9.0000 1.0000
32.7400 11.0000 1.0000
32.8000 10.0000 1.0000
32.8600 13.0000 1.0000
32.9200 11.0000 1.0000
32.9800 10.0000 1.0000
33.0400 13.0000 1.0000
33.1000 16.0000 1.0000
33.1600 15.0000 1.0000
33.2200 13.0000 1.0000
33.2800 10.0000 1.0000
33.3400 12.0000 1.0000
33.4000 17.0000 1.0000
33.4600 10.0000 1.0000
33.5200 11.0000 1.0000
33.5800 16.0000 1.0000
33.6400 14.0000 1.0000
33.7000 14.0000 1.0000
33.7600 9.0000 1.0000
33.8200 7.0000 1.0000
33.8800 10.0000 1.0000
33.9400 15.0000 1.0000
34.0000 18.0000 1.0000
34.0600 9.0000 1.0000
34.1200 15.0000 1.0000
34.1800 14.0000 1.0000
34.2400 17.0000 1.0000
34.3000 10.0000 1.0000
34.3600 8.0000 1.0000
34.4200 9.0000 1.0000
34.4800 12.0000 1.0000
34.5400 6.0000 1.0000
34.6000 11.0000 1.0000
34.6600 13.0000 1.0000
34.7200 17.0000 1.0000
34.7800 12.0000 1.0000
34.8400 12.0000 1.0000
34.9000 6.0000 1.0000
34.9600 11.0000 1.0000
35.0200 6.0000 1.0000
35.0800 16.0000 1.0000
35.1400 13.0000 1.0000
35.2000 7.0000 1.0000
35.2600 11.0000 1.0000
35.3200 10.0000 1.0000
35.3800 13.0000 1.0000
35.4400 12.0000 1.0000
35.5000 14.0000 1.0000
35.5600 13.0000 1.0000
35.6200 12.0000 1.0000
35.6800 9.0000 1.0000
35.7400 7.0000 1.0000
35.8000 13.0000 1.0000
35.8600 13.0000 1.0000
35.9200 12.0000 1.0000
35.9800 11.0000 1.0000
36.0400 9.0000 1.0000
36.1000 12.0000 1.0000
36.1600 13.0000 1.0000
36.2200 8.0000 1.0000
36.2800 13.0000 1.0000
36.3400 11.0000 1.0000
36.4000 13.0000 1.0000
36.4600 5.0000 1.0000
36.5200 20.0000 1.0000
36.5800 13.0000 1.0000
36.6400 12.0000 1.0000
36.7000 16.0000 1.0000
36.7600 8.0000 1.0000
36.8200 8.0000 1.0000
36.8800 9.0000 1.0000
36.9400 14.0000 1.0000
37.0000 14.0000 1.0000
37.0600 12.0000 1.0000
37.1200 11.0000 1.0000
37.1800 8.0000 1.0000
37.2400 10.0000 1.0000
37.3000 8.0000 1.0000
37.3600 10.0000 1.0000
37.4200 5.0000 1.0000
37.4800 11.0000 1.0000
37.5400 8.0000 1.0000
37.6000 16.0000 1.0000
37.6600 13.0000 1.0000
37.7200 6.0000 1.0000
37.7800 10.0000 1.0000
37.8400 9.0000 1.0000
37.9000 15.0000 1.0000
37.9600 14.0000 1.0000
38.0200 8.0000 1.0000
38.0800 9.0000 1.0000
38.1400 9.0000 1.0000
38.2000 9.0000 1.0000
38.2600 13.0000 1.0000
38.3200 12.0000 1.0000
38.3800 12.0000 1.0000
38.4400 13.0000 1.0000
38.5000 12.0000 1.0000
38.5600 12.0000 1.0000
38.6200 9.0000 1.0000
38.6800 11.0000 1.0000
38.7400 9.0000 1.0000
38.8000 13.0000 1.0000
38.8600 7.0000 1.0000
38.9200 13.0000 1.0000
38.9800 8.0000 1.0000
39.0400 12.0000 1.0000
39.1000 16.0000 1.0000
39.1600 6.0000 1.0000
39.2200 12.0000 1.0000
39.2800 8.0000 1.0000
39.3400 8.0000 1.0000
39.4000 14.0000 1.0000
39.4600 7.0000 1.0000
39.5200 12.0000 1.0000
39.5800 11.0000 1.0000
39.6400 7.0000 1.0000
39.7000 17.0000 1.0000
39.7600 12.0000 1.0000
39.8200 12.0000 1.0000
39.8800 7.0000 1.0000
39.9400 10.0000 1.0000
40.0000 7.0000 1.0000
40.0600 14.0000 1.0000
40.1200 9.0000 1.0000
40.1800 9.0000 1.0000
40.2400 5.0000 1.0000
40.3000 14.0000 1.0000
40.3600 9.0000 1.0000
40.4200 13.0000 1.0000
40.4800 6.0000 1.0000
40.5400 7.0000 1.0000
40.6000 9.0000 1.0000
40.6600 9.0000 1.0000
40.7200 9.0000 1.0000
40.7800 13.0000 1.0000
40.8400 13.0000 1.0000
40.9000 9.0000 1.0000
40.9600 12.0000 1.0000
41.0200 10.0000 1.0000
41.0800 8.0000 1.0000
41.1400 12.0000 1.0000
41.2000 11.0000 1.0000
41.2600 10.0000 1.0000
41.3200 6.0000 1.0000
41.3800 9.0000 1.0000
41.4400 11.0000 1.0000
41.5000 14.0000 1.0000
41.5600 18.0000 1.0000
41.6200 10.0000 1.0000
41.6800 20.0000 1.0000
41.7400 6.0000 1.0000
41.8000 12.0000 1.0000
41.8600 7.0000 1.0000
41.9200 13.0000 1.0000
41.9800 10.0000 1.0000
42.0400 18.0000 1.0000
42.1000 9.0000 1.0000
42.1600 12.0000 1.0000
42.2200 15.0000 1.0000
42.2800 8.0000 1.0000
42.3400 20.0000 1.0000
42.4000 8.0000 1.0000
42.4600 14.0000 1.0000
42.5200 15.0000 1.0000
42.5800 10.0000 1.0000
42.6400 14.0000 1.0000
42.7000 11.0000 1.0000
42.7600 14.0000 1.0000
42.8200 14.0000 1.0000
42.8800 16.0000 1.0000
42.9400 11.0000 1.0000
43.0000 16.0000 1.0000
43.0600 16.0000 1.0000
43.1200 18.0000 1.0000
43.1800 16.0000 1.0000
43.2400 26.0000 1.0000
43.3000 23.0000 1.0000
43.3600 23.0000 1.0000
43.4200 15.0000 1.0000
43.4800 25.0000 1.0000
43.5400 23.0000 1.0000
43.6000 37.0000 1.0000
43.6600 33.0000 1.0000
43.7200 55.0000 1.0000
43.7800 51.0000 1.0000
43.8400 57.0000 1.0000
43.9000 77.0000 1.0000
43.9600 90.0000 1.0000
44.0200 117.0000 1.0000
44.0800 175.0000 1.0000
44.1400 211.0000 1.0000
44.2000 302.0000 1.0000
44.2600 446.0000 1.0000
44.3200 703.0000 1.0000
44.3800 873.0000 1.0000
44.4400 1173.0000 1.0000
44.5000 1410.0000 1.0000
44.5600 1391.0000 1.0000
44.6200 1062.0000 1.0000
44.6800 683.0000 1.0000
44.7400 369.0000 1.0000
44.8000 217.0000 1.0000
44.8600 147.0000 1.0000
44.9200 95.0000 1.0000
44.9800 84.0000 1.0000
45.0400 57.0000 1.0000
45.1000 40.0000 1.0000
45.1600 38.0000 1.0000
45.2200 35.0000 1.0000
45.2800 30.0000 1.0000
45.3400 31.0000 1.0000
45.4000 23.0000 1.0000
45.4600 20.0000 1.0000
45.5200 21.0000 1.0000
45.5800 18.0000 1.0000
45.6400 15.0000 1.0000
45.7000 19.0000 1.0000
45.7600 19.0000 1.0000
45.8200 17.0000 1.0000
45.8800 9.0000 1.0000
45.9400 15.0000 1.0000
46.0000 15.0000 1.0000
46.0600 9.0000 1.0000
46.1200 11.0000 1.0000
46.1800 11.0000 1.0000
46.2400 17.0000 1.0000
46.3000 12.0000 1.0000
46.3600 14.0000 1.0000
46.4200 9.0000 1.0000
46.4800 11.0000 1.0000
46.5400 16.0000 1.0000
46.6000 19.0000 1.0000
46.6600 8.0000 1.0000
46.7200 13.0000 1.0000
46.7800 14.0000 1.0000
46.8400 17.0000 1.0000
46.9000 11.0000 1.0000
46.9600 9.0000 1.0000
47.0200 12.0000 1.0000
47.0800 14.0000 1.0000
47.1400 17.0000 1.0000
47.2000 13.0000 1.0000
47.2600 12.0000 1.0000
47.3200 8.0000 1.0000
47.3800 14.0000 1.0000
47.4400 8.0000 1.0000
47.5000 11.0000 1.0000
47.5600 9.0000 1.0000
47.6200 15.0000 1.0000
47.6800 14.0000 1.0000
47.7400 12.0000 1.0000
47.8000 11.0000 1.0000
47.8600 9.0000 1.0000
47.9200 10.0000 1.0000
47.9800 4.0000 1.0000
48.0400 6.0000 1.0000
48.1000 10.0000 1.0000
48.1600 9.0000 1.0000
48.2200 9.0000 1.0000
48.2800 13.0000 1.0000
48.3400 14.0000 1.0000
48.4000 6.0000 1.0000
48.4600 5.0000 1.0000
48.5200 11.0000 1.0000
48.5800 9.0000 1.0000
48.6400 9.0000 1.0000
48.7000 13.0000 1.0000
48.7600 9.0000 1.0000
48.8200 10.0000 1.0000
48.8800 10.0000 1.0000
48.9400 12.0000 1.0000
49.0000 12.0000 1.0000
49.0600 9.0000 1.0000
49.1200 12.0000 1.0000
49.1800 12.0000 1.0000
49.2400 12.0000 1.0000
49.3000 11.0000 1.0000
49.3600 10.0000 1.0000
49.4200 7.0000 1.0000
49.4800 11.0000 1.0000
49.5400 14.0000 1.0000
49.6000 6.0000 1.0000
49.6600 8.0000 1.0000
49.7200 9.0000 1.0000
49.7800 5.0000 1.0000
49.8400 5.0000 1.0000
49.9000 11.0000 1.0000
49.9600 10.0000 1.0000
50.0200 5.0000 1.0000
50.0800 9.0000 1.0000
50.1400 9.0000 1.0000
50.2000 11.0000 1.0000
50.2600 12.0000 1.0000
50.3200 13.0000 1.0000
50.3800 11.0000 1.0000
50.4400 12.0000 1.0000
50.5000 10.0000 1.0000
50.5600 10.0000 1.0000
50.6200 13.0000 1.0000
50.6800 7.0000 1.0000
50.7400 9.0000 1.0000
50.8000 15.0000 1.0000
50.8600 13.0000 1.0000
50.9200 15.0000 1.0000
50.9800 14.0000 1.0000
51.0400 12.0000 1.0000
51.1000 14.0000 1.0000
51.1600 8.0000 1.0000
51.2200 18.0000 1.0000
51.2800 21.0000 1.0000
51.3400 18.0000 1.0000
51.4000 20.0000 1.0000
51.4600 33.0000 1.0000
51.5200 44.0000 1.0000
51.5800 61.0000 1.0000
51.6400 88.0000 1.0000
51.7000 120.0000 1.0000
51.7600 172.0000 1.0000
51.8200 282.0000 1.0000
51.8800 333.0000 1.0000
51.9400 316.0000 1.0000
52.0000 247.0000 1.0000
52.0600 188.0000 1.0000
52.1200 132.0000 1.0000
52.1800 89.0000 1.0000
52.2400 66.0000 1.0000
52.3000 31.0000 1.0000
52.3600 28.0000 1.0000
52.4200 20.0000 1.0000
52.4800 18.0000 1.0000
52.5400 19.0000 1.0000
52.6000 24.0000 1.0000
52.6600 16.0000 1.0000
52.7200 9.0000 1.0000
52.7800 18.0000 1.0000
52.8400 14.0000 1.0000
52.9000 13.0000 1.0000
52.9600 14.0000 1.0000
53.0200 14.0000 1.0000
53.0800 6.0000 1.0000
53.1400 8.0000 1.0000
53.2000 10.0000 1.0000
53.2600 8.0000 1.0000
53.3200 7.0000 1.0000
53.3800 6.0000 1.0000
53.4400 13.0000 1.0000
53.5000 16.0000 1.0000
53.5600 10.0000 1.0000
53.6200 9.0000 1.0000
53.6800 7.0000 1.0000
53.7400 12.0000 1.0000
53.8000 10.0000 1.0000
53.8600 13.0000 1.0000
53.9200 1.0000 1.0000
53.9800 17.0000 1.0000
54.0400 7.0000 1.0000
54.1000 7.0000 1.0000
54.1600 12.0000 1.0000
54.2200 12.0000 1.0000
54.2800 9.0000 1.0000
54.3400 10.0000 1.0000
54.4000 10.0000 1.0000
54.4600 7.0000 1.0000
54.5200 11.0000 1.0000
54.5800 14.0000 1.0000
54.6400 9.0000 1.0000
54.7000 12.0000 1.0000
54.7600 13.0000 1.0000
54.8200 10.0000 1.0000
54.8800 9.0000 1.0000
54.9400 6.0000 1.0000
55.0000 10.0000 1.0000
55.0600 7.0000 1.0000
55.1200 15.0000 1.0000
55.1800 13.0000 1.0000
55.2400 13.0000 1.0000
55.3000 11.0000 1.0000
55.3600 7.0000 1.0000
55.4200 9.0000 1.0000
55.4800 12.0000 1.0000
55.5400 10.0000 1.0000
55.6000 3.0000 1.0000
55.6600 8.0000 1.0000
55.7200 15.0000 1.0000
55.7800 8.0000 1.0000
55.8400 9.0000 1.0000
55.9000 9.0000 1.0000
55.9600 12.0000 1.0000
56.0200 11.0000 1.0000
56.0800 7.0000 1.0000
56.1400 12.0000 1.0000
56.2000 16.0000 1.0000
56.2600 10.0000 1.0000
56.3200 8.0000 1.0000
56.3800 6.0000 1.0000
56.4400 12.0000 1.0000
56.5000 8.0000 1.0000
56.5600 9.0000 1.0000
56.6200 6.0000 1.0000
56.6800 6.0000 1.0000
56.7400 14.0000 1.0000
56.8000 15.0000 1.0000
56.8600 4.0000 1.0000
56.9200 11.0000 1.0000
56.9800 15.0000 1.0000
57.0400 8.0000 1.0000
57.1000 8.0000 1.0000
57.1600 8.0000 1.0000
57.2200 9.0000 1.0000
57.2800 2.0000 1.0000
57.3400 8.0000 1.0000
57.4000 11.0000 1.0000
57.4600 7.0000 1.0000
57.5200 11.0000 1.0000
57.5800 7.0000 1.0000
57.6400 6.0000 1.0000
57.7000 7.0000 1.0000
57.7600 8.0000 1.0000
57.8200 12.0000 1.0000
57.8800 10.0000 1.0000
57.9400 11.0000 1.0000
58.0000 6.0000 1.0000
58.0600 14.0000 1.0000
58.1200 4.0000 1.0000
58.1800 12.0000 1.0000
58.2400 13.0000 1.0000
58.3000 12.0000 1.0000
58.3600 12.0000 1.0000
58.4200 6.0000 1.0000
58.4800 10.0000 1.0000
58.5400 11.0000 1.0000
58.6000 10.0000 1.0000
58.6600 8.0000 1.0000
58.7200 6.0000 1.0000
58.7800 9.0000 1.0000
58.8400 12.0000 1.0000
58.9000 8.0000 1.0000
58.9600 13.0000 1.0000
59.0200 9.0000 1.0000
59.0800 7.0000 1.0000
59.1400 8.0000 1.0000
59.2000 4.0000 1.0000
59.2600 17.0000 1.0000
59.3200 7.0000 1.0000
59.3800 7.0000 1.0000
59.4400 7.0000 1.0000
59.5000 14.0000 1.0000
59.5600 14.0000 1.0000
59.6200 11.0000 1.0000
59.6800 6.0000 1.0000
59.7400 9.0000 1.0000
59.8000 11.0000 1.0000
59.8600 14.0000 1.0000
59.9200 10.0000 1.0000
59.9800 16.0000 1.0000
60.0400 11.0000 1.0000
60.1000 10.0000 1.0000
60.1600 5.0000 1.0000
60.2200 7.0000 1.0000
60.2800 11.0000 1.0000
60.3400 7.0000 1.0000
60.4000 7.0000 1.0000
60.4600 13.0000 1.0000
60.5200 12.0000 1.0000
60.5800 9.0000 1.0000
60.6400 6.0000 1.0000
60.7000 9.0000 1.0000
60.7600 11.0000 1.0000
60.8200 8.0000 1.0000
60.8800 8.0000 1.0000
60.9400 9.0000 1.0000
61.0000 9.0000 1.0000
61.0600 9.0000 1.0000
61.1200 10.0000 1.0000
61.1800 14.0000 1.0000
61.2400 7.0000 1.0000
61.3000 11.0000 1.0000
61.3600 11.0000 1.0000
61.4200 10.0000 1.0000
61.4800 9.0000 1.0000
61.5400 13.0000 1.0000
61.6000 15.0000 1.0000
61.6600 8.0000 1.0000
61.7200 15.0000 1.0000
61.7800 13.0000 1.0000
61.8400 8.0000 1.0000
61.9000 10.0000 1.0000
61.9600 6.0000 1.0000
62.0200 8.0000 1.0000
62.0800 10.0000 1.0000
62.1400 6.0000 1.0000
62.2000 17.0000 1.0000
62.2600 10.0000 1.0000
62.3200 11.0000 1.0000
62.3800 9.0000 1.0000
62.4400 9.0000 1.0000
62.5000 7.0000 1.0000
62.5600 10.0000 1.0000
62.6200 8.0000 1.0000
62.6800 8.0000 1.0000
62.7400 11.0000 1.0000
62.8000 14.0000 1.0000
62.8600 6.0000 1.0000
62.9200 13.0000 1.0000
62.9800 10.0000 1.0000
63.0400 6.0000 1.0000
63.1000 6.0000 1.0000
63.1600 17.0000 1.0000
63.2200 11.0000 1.0000
63.2800 11.0000 1.0000
63.3400 14.0000 1.0000
63.4000 11.0000 1.0000
63.4600 7.0000 1.0000
63.5200 12.0000 1.0000
63.5800 14.0000 1.0000
63.6400 12.0000 1.0000
63.7000 15.0000 1.0000
63.7600 13.0000 1.0000
63.8200 13.0000 1.0000
63.8800 12.0000 1.0000
63.9400 17.0000 1.0000
64.0000 15.0000 1.0000
64.0600 24.0000 1.0000
64.1200 34.0000 1.0000
64.1800 26.0000 1.0000
64.2400 50.0000 1.0000
64.3000 49.0000 1.0000
64.3600 62.0000 1.0000
64.4200 62.0000 1.0000
64.4800 84.0000 1.0000
64.5400 87.0000 1.0000
64.6000 116.0000 1.0000
64.6600 102.0000 1.0000
64.7200 102.0000 1.0000
64.7800 66.0000 1.0000
64.8400 78.0000 1.0000
64.9000 46.0000 1.0000
64.9600 44.0000 1.0000
65.0200 36.0000 1.0000
65.0800 27.0000 1.0000
65.1400 22.0000 1.0000
65.2000 30.0000 1.0000
65.2600 18.0000 1.0000
65.3200 14.0000 1.0000
65.3800 9.0000 1.0000
65.4400 19.0000 1.0000
65.5000 15.0000 1.0000
65.5600 9.0000 1.0000
65.6200 12.0000 1.0000
65.6800 10.0000 1.0000
65.7400 13.0000 1.0000
65.8000 16.0000 1.0000
65.8600 6.0000 1.0000
65.9200 6.0000 1.0000
65.9800 9.0000 1.0000
66.0400 6.0000 1.0000
66.1000 6.0000 1.0000
66.1600 11.0000 1.0000
66.2200 13.0000 1.0000
66.2800 13.0000 1.0000
66.3400 12.0000 1.0000
66.4000 6.0000 1.0000
66.4600 14.0000 1.0000
66.5200 5.0000 1.0000
66.5800 12.0000 1.0000
66.6400 13.0000 1.0000
66.7000 9.0000 1.0000
66.7600 17.0000 1.0000
66.8200 13.0000 1.0000
66.8800 10.0000 1.0000
66.9400 10.0000 1.0000
67.0000 9.0000 1.0000
67.0600 10.0000 1.0000
67.1200 11.0000 1.0000
67.1800 6.0000 1.0000
67.2400 8.0000 1.0000
67.3000 7.0000 1.0000
67.3600 7.0000 1.0000
67.4200 7.0000 1.0000
67.4800 11.0000 1.0000
67.5400 5.0000 1.0000
67.6000 10.0000 1.0000
67.6600 7.0000 1.0000
67.7200 13.0000 1.0000
67.7800 12.0000 1.0000
67.8400 12.0000 1.0000
67.9000 7.0000 1.0000
67.9600 8.0000 1.0000
68.0200 5.0000 1.0000
68.0800 12.0000 1.0000
68.1400 9.0000 1.0000
68.2000 13.0000 1.0000
68.2600 10.0000 1.0000
68.3200 14.0000 1.0000
68.3800 14.0000 1.0000
68.4400 13.0000 1.0000
68.5000 14.0000 1.0000
68.5600 11.0000 1.0000
68.6200 13.0000 1.0000
68.6800 9.0000 1.0000
68.7400 12.0000 1.0000
68.8000 10.0000 1.0000
68.8600 6.0000 1.0000
68.9200 15.0000 1.0000
68.9800 12.0000 1.0000
69.0400 11.0000 1.0000
69.1000 11.0000 1.0000
69.1600 6.0000 1.0000
69.2200 11.0000 1.0000
69.2800 12.0000 1.0000
69.3400 11.0000 1.0000
69.4000 8.0000 1.0000
69.4600 9.0000 1.0000
69.5200 6.0000 1.0000
69.5800 7.0000 1.0000
69.6400 16.0000 1.0000
69.7000 11.0000 1.0000
69.7600 12.0000 1.0000
69.8200 11.0000 1.0000
69.8800 12.0000 1.0000
69.9400 9.0000 1.0000
70.0000 20.0000 1.0000
*RAS_INT_END
*RAS_DATA_END