File: Examples/data/HoB21.ras
*RAS_DATA_START
*RAS_HEADER_START
*DISP_FMT_X "%.2f"
*DISP_FMT_Y "%.0f"
*DISP_FULLSCALE "5580.0000000000"
*DISP_LINE_COLOR "255.0000000000"
*DISP_LINE_STYLE "0.0000000000"
*DISP_LINE_WIDTH "0.2500000000"
*DISP_NOTE "測定データ-4"
*DISP_OFFSET_Y "0.0000000000"
*DISP_PEAKSEARCH_UNIT_Y "cps"
*DISP_RANGE_BOTTOM "0.0000000000"
*DISP_RANGE_LEFT "10.0000000000"
*DISP_RANGE_LOGCUTOFF "0.0100000000"
*DISP_RANGE_RIGHT "70.0000000000"
*DISP_RANGE_TOP "5580.0000000000"
*DISP_SCALE_MODE_Y "0.0000000000"
*DISP_TAB_NAME "2θ/θ"
*DISP_TITLE_Y "強度"
*DISP_UNIT_Y "cps"
*DISP_WINDOW_NAME "MSG_MACROENGINE"
*FILE_COMMENT " "
*FILE_MD5 ""
*FILE_MEMO " "
*FILE_OPERATOR "Administrator"
*FILE_SAMPLE " "
*FILE_TYPE "RAS_RAW"
*FILE_USERGROUP "システムマネージャ"
*FILE_VERSION "1.0000000000"
*HW_ATTACHMENT_ID "ATT1025"
*HW_ATTACHMENT_NAME "標準試料台|Standard Sample Holder"
*HW_COUNTER_ID-0 "CUT0021"
*HW_COUNTER_ID-1 "CUT0020"
*HW_COUNTER_ID-2 "CUT0020"
*HW_COUNTER_ID-3 "CMC0021"
*HW_COUNTER_NAME-0 "SC-70|SC-70"
*HW_COUNTER_NAME-1 "None|None"
*HW_COUNTER_NAME-2 "None|None"
*HW_COUNTER_NAME-3 "検出器モノクロメータ|Detector monochromator"
*HW_COUNTER_SELECT_NAME "SC-70|SC-70"
*HW_ECP_HV "641.5000000000"
*HW_ECP_HV_UNIT "V"
*HW_GONIOMETER_ID "GON0070"
*HW_GONIOMETER_NAME "MiniFlex 300/600|MiniFlex 300/600"
*HW_GONIOMETER_RADIUS-0 "79.0"
*HW_GONIOMETER_RADIUS-1 "91.5"
*HW_GONIOMETER_RADIUS-2 "150.0"
*HW_GONIOMETER_RADIUS-3 "0"
*HW_GONIOMETER_RADIUS-4 "103.4"
*HW_GONIOMETER_RADIUS-5 "150.0"
*HW_GONIOMETER_RADIUS-6 "46.6"
*HW_GONIOMETER_RADIUS-7 "160.0"
*HW_I_OPT_ID-0 "ISL0021"
*HW_I_OPT_ID-1 "ISO0021"
*HW_I_OPT_NAME-0 "発散スリット|Divergence slit"
*HW_I_OPT_NAME-1 "入射平行スリット|Incident parallel slit"
*HW_R_ATTENUATER_AUTOMODE "0"
*HW_R_OPT_ID-0 "RSS0021"
*HW_R_OPT_ID-1 "RSO0021"
*HW_R_OPT_ID-2 "RRS0021"
*HW_R_OPT_NAME-0 "散乱スリット|Scattering slit"
*HW_R_OPT_NAME-1 "受光平行スリット|Receiving soller slit"
*HW_R_OPT_NAME-2 "受光スリット|Receiving slit"
*HW_SAMPLE_HOLDER_ID "SMP0000"
*HW_SAMPLE_HOLDER_NAME "無し|None"
*HW_XG_CURRENT_MAX "15"
*HW_XG_CURRENT_MIN "2"
*HW_XG_CURRENT_RESOLUTION "1"
*HW_XG_CURRENT_UNIT "mA"
*HW_XG_FOCUS "1mm x 10mm"
*HW_XG_FOCUS_TYPE "Normal"
*HW_XG_ID ""
*HW_XG_NAME "300W/600W 封入管-A|300W/600W Sealed tube-A"
*HW_XG_TARGET_ATOMIC_NUMBER "29.0000000000"
*HW_XG_TARGET_NAME "Cu"
*HW_XG_TYPE "Hermetic"
*HW_XG_VOLTAGE_MAX "40"
*HW_XG_VOLTAGE_MIN "20"
*HW_XG_VOLTAGE_RESOLUTION "1"
*HW_XG_VOLTAGE_UNIT "kV"
*HW_XG_WATT_MAX "1"
*HW_XG_WATT_UNIT "kW"
*HW_XG_WAVE_LENGTH_ALPHA1 "1.540593"
*HW_XG_WAVE_LENGTH_ALPHA2 "1.544414"
*HW_XG_WAVE_LENGTH_BETA "1.392250"
*MEAS_COND_AXIS_NAME-0 "2θ/θ"
*MEAS_COND_AXIS_NAME-1 "Soller(inc.)"
*MEAS_COND_AXIS_NAME-2 "IHS"
*MEAS_COND_AXIS_NAME-3 "DS"
*MEAS_COND_AXIS_NAME-4 "SS"
*MEAS_COND_AXIS_NAME-5 "Soller(rec.)"
*MEAS_COND_AXIS_NAME-6 "RS"
*MEAS_COND_AXIS_NAME-7 "フィルター"
*MEAS_COND_AXIS_NAME-8 "モノクロメータ"
*MEAS_COND_AXIS_NAME-9 "HV"
*MEAS_COND_AXIS_NAME-10 "PHA"
*MEAS_COND_AXIS_NAME_INTERNAL-0 "TwoThetaTheta"
*MEAS_COND_AXIS_NAME_INTERNAL-1 "IncidentSollerSlit"
*MEAS_COND_AXIS_NAME_INTERNAL-2 "IncidentAxdSlit"
*MEAS_COND_AXIS_NAME_INTERNAL-3 "IncidentSlitBox"
*MEAS_COND_AXIS_NAME_INTERNAL-4 "ReceivingSlitBox1"
*MEAS_COND_AXIS_NAME_INTERNAL-5 "ReceivingSollerSlit"
*MEAS_COND_AXIS_NAME_INTERNAL-6 "ReceivingSlitBox2"
*MEAS_COND_AXIS_NAME_INTERNAL-7 "Filter"
*MEAS_COND_AXIS_NAME_INTERNAL-8 "CounterMonochromator"
*MEAS_COND_AXIS_NAME_INTERNAL-9 "HV"
*MEAS_COND_AXIS_NAME_INTERNAL-10 "PHA"
*MEAS_COND_AXIS_NAME_MAGICNO-0 "268632064.0000000000"
*MEAS_COND_AXIS_NAME_MAGICNO-1 "20971521.0000000000"
*MEAS_COND_AXIS_NAME_MAGICNO-2 "22020097.0000000000"
*MEAS_COND_AXIS_NAME_MAGICNO-3 "22020097.0000000000"
*MEAS_COND_AXIS_NAME_MAGICNO-4 "23068673.0000000000"
*MEAS_COND_AXIS_NAME_MAGICNO-5 "20971521.0000000000"
*MEAS_COND_AXIS_NAME_MAGICNO-6 "23068673.0000000000"
*MEAS_COND_AXIS_NAME_MAGICNO-7 "20971521.0000000000"
*MEAS_COND_AXIS_NAME_MAGICNO-8 "20971521.0000000000"
*MEAS_COND_AXIS_NAME_MAGICNO-9 "0.0000000000"
*MEAS_COND_AXIS_NAME_MAGICNO-10 "0.0000000000"
*MEAS_COND_AXIS_OFFSET-0 "0.0000000000"
*MEAS_COND_AXIS_OFFSET-1 "-"
*MEAS_COND_AXIS_OFFSET-2 "-"
*MEAS_COND_AXIS_OFFSET-3 "-"
*MEAS_COND_AXIS_OFFSET-4 "-"
*MEAS_COND_AXIS_OFFSET-5 "-"
*MEAS_COND_AXIS_OFFSET-6 "-"
*MEAS_COND_AXIS_OFFSET-7 "-"
*MEAS_COND_AXIS_OFFSET-8 "-"
*MEAS_COND_AXIS_OFFSET-9 "-"
*MEAS_COND_AXIS_OFFSET-10 "-"
*MEAS_COND_AXIS_POSITION-0 "10.0000000000"
*MEAS_COND_AXIS_POSITION-1 "5.0deg"
*MEAS_COND_AXIS_POSITION-2 "10.0mm"
*MEAS_COND_AXIS_POSITION-3 "1.250deg"
*MEAS_COND_AXIS_POSITION-4 "1.250deg"
*MEAS_COND_AXIS_POSITION-5 "5.0deg"
*MEAS_COND_AXIS_POSITION-6 "0.3mm"
*MEAS_COND_AXIS_POSITION-7 "None"
*MEAS_COND_AXIS_POSITION-8 "Bent"
*MEAS_COND_AXIS_POSITION-9 "641.5000000000"
*MEAS_COND_AXIS_POSITION-10 "566.2500000000"
*MEAS_COND_AXIS_UNIT-0 "deg"
*MEAS_COND_AXIS_UNIT-1 ""
*MEAS_COND_AXIS_UNIT-2 ""
*MEAS_COND_AXIS_UNIT-3 ""
*MEAS_COND_AXIS_UNIT-4 ""
*MEAS_COND_AXIS_UNIT-5 ""
*MEAS_COND_AXIS_UNIT-6 ""
*MEAS_COND_AXIS_UNIT-7 ""
*MEAS_COND_AXIS_UNIT-8 ""
*MEAS_COND_AXIS_UNIT-9 "V"
*MEAS_COND_AXIS_UNIT-10 "mV"
*MEAS_COND_COUNTER_CNTLOSS_CORR "0.0000000000"
*MEAS_COND_COUNTER_PHABASE "566.2500000000"
*MEAS_COND_COUNTER_PHAWINDOW "878.7500000000"
*MEAS_COND_COUNTER_PHA_UNIT "mV"
*MEAS_COND_COUNTER_TAUDIFF "0.2500000000"
*MEAS_COND_COUNTER_TAUINT "0.7500000000"
*MEAS_COND_IRRADIATION_MODE "OFF"
*MEAS_COND_IRRADIATION_WIDTH ""
*MEAS_COND_OPT_ATTR " "
*MEAS_COND_OPT_NAME ""
*MEAS_COND_UNSYMMETRIC_MODE "OFF"
*MEAS_COND_XG_CURRENT "15.0000000000"
*MEAS_COND_XG_VOLTAGE "40.0000000000"
*MEAS_COND_XG_WAVE_TYPE "Ka"
*MEAS_DATA_COUNT "3001.0000000000"
*MEAS_SCAN_AXIS_X "2θ/θ"
*MEAS_SCAN_AXIS_X_INTERNAL "TwoThetaTheta"
*MEAS_SCAN_END_TIME "08/05/19 18:53:03"
*MEAS_SCAN_MODE "CONTINUOUS"
*MEAS_SCAN_MONITOR "0"
*MEAS_SCAN_RESOLUTION_X "0.0025"
*MEAS_SCAN_SPEED "3.0000"
*MEAS_SCAN_SPEED_UNIT "deg/min"
*MEAS_SCAN_START "10.0000000000"
*MEAS_SCAN_START_TIME "08/05/19 18:32:54"
*MEAS_SCAN_STEP "0.0200000000"
*MEAS_SCAN_STOP "70.0000000000"
*MEAS_SCAN_UNIT_X "deg"
*MEAS_SCAN_UNIT_Y "counts"
*SLIT_SYSTEM "0"
*RAS_HEADER_END
*RAS_INT_START
10.0000 17.0000 1.0000
10.0600 21.0000 1.0000
10.1200 22.0000 1.0000
10.1800 21.0000 1.0000
10.2400 15.0000 1.0000
10.3000 22.0000 1.0000
10.3600 25.0000 1.0000
10.4200 20.0000 1.0000
10.4800 20.0000 1.0000
10.5400 18.0000 1.0000
10.6000 15.0000 1.0000
10.6600 18.0000 1.0000
10.7200 18.0000 1.0000
10.7800 14.0000 1.0000
10.8400 19.0000 1.0000
10.9000 16.0000 1.0000
10.9600 23.0000 1.0000
11.0200 21.0000 1.0000
11.0800 21.0000 1.0000
11.1400 16.0000 1.0000
11.2000 14.0000 1.0000
11.2600 25.0000 1.0000
11.3200 11.0000 1.0000
11.3800 21.0000 1.0000
11.4400 17.0000 1.0000
11.5000 26.0000 1.0000
11.5600 17.0000 1.0000
11.6200 26.0000 1.0000
11.6800 18.0000 1.0000
11.7400 22.0000 1.0000
11.8000 17.0000 1.0000
11.8600 27.0000 1.0000
11.9200 23.0000 1.0000
11.9800 25.0000 1.0000
12.0400 27.0000 1.0000
12.1000 19.0000 1.0000
12.1600 24.0000 1.0000
12.2200 17.0000 1.0000
12.2800 20.0000 1.0000
12.3400 24.0000 1.0000
12.4000 21.0000 1.0000
12.4600 20.0000 1.0000
12.5200 15.0000 1.0000
12.5800 27.0000 1.0000
12.6400 20.0000 1.0000
12.7000 26.0000 1.0000
12.7600 18.0000 1.0000
12.8200 28.0000 1.0000
12.8800 13.0000 1.0000
12.9400 21.0000 1.0000
13.0000 32.0000 1.0000
13.0600 24.0000 1.0000
13.1200 28.0000 1.0000
13.1800 25.0000 1.0000
13.2400 25.0000 1.0000
13.3000 33.0000 1.0000
13.3600 30.0000 1.0000
13.4200 21.0000 1.0000
13.4800 23.0000 1.0000
13.5400 29.0000 1.0000
13.6000 22.0000 1.0000
13.6600 31.0000 1.0000
13.7200 24.0000 1.0000
13.7800 24.0000 1.0000
13.8400 23.0000 1.0000
13.9000 31.0000 1.0000
13.9600 32.0000 1.0000
14.0200 23.0000 1.0000
14.0800 18.0000 1.0000
14.1400 23.0000 1.0000
14.2000 24.0000 1.0000
14.2600 24.0000 1.0000
14.3200 18.0000 1.0000
14.3800 34.0000 1.0000
14.4400 29.0000 1.0000
14.5000 23.0000 1.0000
14.5600 24.0000 1.0000
14.6200 26.0000 1.0000
14.6800 22.0000 1.0000
14.7400 32.0000 1.0000
14.8000 16.0000 1.0000
14.8600 32.0000 1.0000
14.9200 27.0000 1.0000
14.9800 30.0000 1.0000
15.0400 25.0000 1.0000
15.1000 29.0000 1.0000
15.1600 20.0000 1.0000
15.2200 21.0000 1.0000
15.2800 22.0000 1.0000
15.3400 24.0000 1.0000
15.4000 34.0000 1.0000
15.4600 18.0000 1.0000
15.5200 22.0000 1.0000
15.5800 35.0000 1.0000
15.6400 39.0000 1.0000
15.7000 26.0000 1.0000
15.7600 26.0000 1.0000
15.8200 32.0000 1.0000
15.8800 37.0000 1.0000
15.9400 34.0000 1.0000
16.0000 24.0000 1.0000
16.0600 32.0000 1.0000
16.1200 23.0000 1.0000
16.1800 32.0000 1.0000
16.2400 32.0000 1.0000
16.3000 28.0000 1.0000
16.3600 27.0000 1.0000
16.4200 31.0000 1.0000
16.4800 33.0000 1.0000
16.5400 35.0000 1.0000
16.6000 29.0000 1.0000
16.6600 32.0000 1.0000
16.7200 31.0000 1.0000
16.7800 28.0000 1.0000
16.8400 29.0000 1.0000
16.9000 28.0000 1.0000
16.9600 21.0000 1.0000
17.0200 22.0000 1.0000
17.0800 30.0000 1.0000
17.1400 41.0000 1.0000
17.2000 22.0000 1.0000
17.2600 35.0000 1.0000
17.3200 35.0000 1.0000
17.3800 23.0000 1.0000
17.4400 41.0000 1.0000
17.5000 35.0000 1.0000
17.5600 31.0000 1.0000
17.6200 32.0000 1.0000
17.6800 30.0000 1.0000
17.7400 27.0000 1.0000
17.8000 30.0000 1.0000
17.8600 27.0000 1.0000
17.9200 43.0000 1.0000
17.9800 35.0000 1.0000
18.0400 44.0000 1.0000
18.1000 29.0000 1.0000
18.1600 42.0000 1.0000
18.2200 40.0000 1.0000
18.2800 27.0000 1.0000
18.3400 41.0000 1.0000
18.4000 34.0000 1.0000
18.4600 34.0000 1.0000
18.5200 30.0000 1.0000
18.5800 31.0000 1.0000
18.6400 42.0000 1.0000
18.7000 31.0000 1.0000
18.7600 29.0000 1.0000
18.8200 29.0000 1.0000
18.8800 23.0000 1.0000
18.9400 27.0000 1.0000
19.0000 27.0000 1.0000
19.0600 41.0000 1.0000
19.1200 30.0000 1.0000
19.1800 38.0000 1.0000
19.2400 37.0000 1.0000
19.3000 24.0000 1.0000
19.3600 30.0000 1.0000
19.4200 47.0000 1.0000
19.4800 44.0000 1.0000
19.5400 42.0000 1.0000
19.6000 41.0000 1.0000
19.6600 37.0000 1.0000
19.7200 36.0000 1.0000
19.7800 39.0000 1.0000
19.8400 35.0000 1.0000
19.9000 43.0000 1.0000
19.9600 32.0000 1.0000
20.0200 40.0000 1.0000
20.0800 32.0000 1.0000
20.1400 31.0000 1.0000
20.2000 45.0000 1.0000
20.2600 37.0000 1.0000
20.3200 40.0000 1.0000
20.3800 32.0000 1.0000
20.4400 46.0000 1.0000
20.5000 42.0000 1.0000
20.5600 24.0000 1.0000
20.6200 33.0000 1.0000
20.6800 32.0000 1.0000
20.7400 43.0000 1.0000
20.8000 31.0000 1.0000
20.8600 36.0000 1.0000
20.9200 37.0000 1.0000
20.9800 35.0000 1.0000
21.0400 33.0000 1.0000
21.1000 44.0000 1.0000
21.1600 43.0000 1.0000
21.2200 20.0000 1.0000
21.2800 36.0000 1.0000
21.3400 50.0000 1.0000
21.4000 41.0000 1.0000
21.4600 43.0000 1.0000
21.5200 56.0000 1.0000
21.5800 42.0000 1.0000
21.6400 45.0000 1.0000
21.7000 52.0000 1.0000
21.7600 52.0000 1.0000
21.8200 53.0000 1.0000
21.8800 53.0000 1.0000
21.9400 89.0000 1.0000
22.0000 140.0000 1.0000
22.0600 225.0000 1.0000
22.1200 162.0000 1.0000
22.1800 101.0000 1.0000
22.2400 57.0000 1.0000
22.3000 64.0000 1.0000
22.3600 52.0000 1.0000
22.4200 33.0000 1.0000
22.4800 44.0000 1.0000
22.5400 68.0000 1.0000
22.6000 58.0000 1.0000
22.6600 90.0000 1.0000
22.7200 95.0000 1.0000
22.7800 111.0000 1.0000
22.8400 138.0000 1.0000
22.9000 184.0000 1.0000
22.9600 236.0000 1.0000
23.0200 360.0000 1.0000
23.0800 471.0000 1.0000
23.1400 660.0000 1.0000
23.2000 737.0000 1.0000
23.2600 654.0000 1.0000
23.3200 410.0000 1.0000
23.3800 284.0000 1.0000
23.4400 186.0000 1.0000
23.5000 135.0000 1.0000
23.5600 122.0000 1.0000
23.6200 96.0000 1.0000
23.6800 95.0000 1.0000
23.7400 57.0000 1.0000
23.8000 51.0000 1.0000
23.8600 46.0000 1.0000
23.9200 51.0000 1.0000
23.9800 42.0000 1.0000
24.0400 54.0000 1.0000
24.1000 50.0000 1.0000
24.1600 48.0000 1.0000
24.2200 35.0000 1.0000
24.2800 43.0000 1.0000
24.3400 39.0000 1.0000
24.4000 42.0000 1.0000
24.4600 46.0000 1.0000
24.5200 31.0000 1.0000
24.5800 34.0000 1.0000
24.6400 41.0000 1.0000
24.7000 41.0000 1.0000
24.7600 40.0000 1.0000
24.8200 36.0000 1.0000
24.8800 51.0000 1.0000
24.9400 72.0000 1.0000
25.0000 92.0000 1.0000
25.0600 88.0000 1.0000
25.1200 69.0000 1.0000
25.1800 52.0000 1.0000
25.2400 37.0000 1.0000
25.3000 32.0000 1.0000
25.3600 29.0000 1.0000
25.4200 34.0000 1.0000
25.4800 43.0000 1.0000
25.5400 40.0000 1.0000
25.6000 40.0000 1.0000
25.6600 36.0000 1.0000
25.7200 36.0000 1.0000
25.7800 46.0000 1.0000
25.8400 39.0000 1.0000
25.9000 39.0000 1.0000
25.9600 32.0000 1.0000
26.0200 37.0000 1.0000
26.0800 36.0000 1.0000
26.1400 49.0000 1.0000
26.2000 32.0000 1.0000
26.2600 29.0000 1.0000
26.3200 40.0000 1.0000
26.3800 30.0000 1.0000
26.4400 44.0000 1.0000
26.5000 34.0000 1.0000
26.5600 38.0000 1.0000
26.6200 35.0000 1.0000
26.6800 31.0000 1.0000
26.7400 33.0000 1.0000
26.8000 41.0000 1.0000
26.8600 43.0000 1.0000
26.9200 40.0000 1.0000
26.9800 32.0000 1.0000
27.0400 28.0000 1.0000
27.1000 38.0000 1.0000
27.1600 32.0000 1.0000
27.2200 42.0000 1.0000
27.2800 27.0000 1.0000
27.3400 35.0000 1.0000
27.4000 49.0000 1.0000
27.4600 52.0000 1.0000
27.5200 29.0000 1.0000
27.5800 43.0000 1.0000
27.6400 42.0000 1.0000
27.7000 34.0000 1.0000
27.7600 40.0000 1.0000
27.8200 57.0000 1.0000
27.8800 58.0000 1.0000
27.9400 101.0000 1.0000
28.0000 145.0000 1.0000
28.0600 202.0000 1.0000
28.1200 125.0000 1.0000
28.1800 69.0000 1.0000
28.2400 51.0000 1.0000
28.3000 36.0000 1.0000
28.3600 57.0000 1.0000
28.4200 58.0000 1.0000
28.4800 46.0000 1.0000
28.5400 53.0000 1.0000
28.6000 57.0000 1.0000
28.6600 48.0000 1.0000
28.7200 40.0000 1.0000
28.7800 43.0000 1.0000
28.8400 39.0000 1.0000
28.9000 44.0000 1.0000
28.9600 42.0000 1.0000
29.0200 59.0000 1.0000
29.0800 65.0000 1.0000
29.1400 53.0000 1.0000
29.2000 44.0000 1.0000
29.2600 41.0000 1.0000
29.3200 42.0000 1.0000
29.3800 33.0000 1.0000
29.4400 37.0000 1.0000
29.5000 45.0000 1.0000
29.5600 32.0000 1.0000
29.6200 47.0000 1.0000
29.6800 46.0000 1.0000
29.7400 36.0000 1.0000
29.8000 41.0000 1.0000
29.8600 62.0000 1.0000
29.9200 47.0000 1.0000
29.9800 45.0000 1.0000
30.0400 43.0000 1.0000
30.1000 42.0000 1.0000
30.1600 49.0000 1.0000
30.2200 55.0000 1.0000
30.2800 49.0000 1.0000
30.3400 54.0000 1.0000
30.4000 55.0000 1.0000
30.4600 69.0000 1.0000
30.5200 60.0000 1.0000
30.5800 68.0000 1.0000
30.6400 78.0000 1.0000
30.7000 125.0000 1.0000
30.7600 141.0000 1.0000
30.8200 169.0000 1.0000
30.8800 177.0000 1.0000
30.9400 205.0000 1.0000
31.0000 273.0000 1.0000
31.0600 377.0000 1.0000
31.1200 531.0000 1.0000
31.1800 818.0000 1.0000
31.2400 1262.0000 1.0000
31.3000 1686.0000 1.0000
31.3600 1860.0000 1.0000
31.4200 1558.0000 1.0000
31.4800 1062.0000 1.0000
31.5400 626.0000 1.0000
31.6000 356.0000 1.0000
31.6600 292.0000 1.0000
31.7200 201.0000 1.0000
31.7800 158.0000 1.0000
31.8400 131.0000 1.0000
31.9000 121.0000 1.0000
31.9600 98.0000 1.0000
32.0200 102.0000 1.0000
32.0800 89.0000 1.0000
32.1400 69.0000 1.0000
32.2000 56.0000 1.0000
32.2600 63.0000 1.0000
32.3200 61.0000 1.0000
32.3800 49.0000 1.0000
32.4400 56.0000 1.0000
32.5000 41.0000 1.0000
32.5600 52.0000 1.0000
32.6200 36.0000 1.0000
32.6800 45.0000 1.0000
32.7400 48.0000 1.0000
32.8000 54.0000 1.0000
32.8600 51.0000 1.0000
32.9200 46.0000 1.0000
32.9800 50.0000 1.0000
33.0400 36.0000 1.0000
33.1000 47.0000 1.0000
33.1600 42.0000 1.0000
33.2200 49.0000 1.0000
33.2800 44.0000 1.0000
33.3400 48.0000 1.0000
33.4000 46.0000 1.0000
33.4600 40.0000 1.0000
33.5200 67.0000 1.0000
33.5800 115.0000 1.0000
33.6400 163.0000 1.0000
33.7000 139.0000 1.0000
33.7600 84.0000 1.0000
33.8200 49.0000 1.0000
33.8800 49.0000 1.0000
33.9400 43.0000 1.0000
34.0000 58.0000 1.0000
34.0600 39.0000 1.0000
34.1200 36.0000 1.0000
34.1800 29.0000 1.0000
34.2400 29.0000 1.0000
34.3000 35.0000 1.0000
34.3600 32.0000 1.0000
34.4200 33.0000 1.0000
34.4800 38.0000 1.0000
34.5400 39.0000 1.0000
34.6000 37.0000 1.0000
34.6600 20.0000 1.0000
34.7200 35.0000 1.0000
34.7800 32.0000 1.0000
34.8400 29.0000 1.0000
34.9000 28.0000 1.0000
34.9600 48.0000 1.0000
35.0200 26.0000 1.0000
35.0800 33.0000 1.0000
35.1400 23.0000 1.0000
35.2000 30.0000 1.0000
35.2600 30.0000 1.0000
35.3200 31.0000 1.0000
35.3800 36.0000 1.0000
35.4400 35.0000 1.0000
35.5000 30.0000 1.0000
35.5600 46.0000 1.0000
35.6200 51.0000 1.0000
35.6800 46.0000 1.0000
35.7400 66.0000 1.0000
35.8000 56.0000 1.0000
35.8600 80.0000 1.0000
35.9200 114.0000 1.0000
35.9800 203.0000 1.0000
36.0400 224.0000 1.0000
36.1000 161.0000 1.0000
36.1600 108.0000 1.0000
36.2200 59.0000 1.0000
36.2800 58.0000 1.0000
36.3400 46.0000 1.0000
36.4000 29.0000 1.0000
36.4600 45.0000 1.0000
36.5200 43.0000 1.0000
36.5800 28.0000 1.0000
36.6400 33.0000 1.0000
36.7000 32.0000 1.0000
36.7600 27.0000 1.0000
36.8200 29.0000 1.0000
36.8800 42.0000 1.0000
36.9400 33.0000 1.0000
37.0000 40.0000 1.0000
37.0600 35.0000 1.0000
37.1200 25.0000 1.0000
37.1800 29.0000 1.0000
37.2400 29.0000 1.0000
37.3000 35.0000 1.0000
37.3600 40.0000 1.0000
37.4200 41.0000 1.0000
37.4800 34.0000 1.0000
37.5400 38.0000 1.0000
37.6000 44.0000 1.0000
37.6600 31.0000 1.0000
37.7200 44.0000 1.0000
37.7800 48.0000 1.0000
37.8400 54.0000 1.0000
37.9000 49.0000 1.0000
37.9600 54.0000 1.0000
38.0200 50.0000 1.0000
38.0800 45.0000 1.0000
38.1400 47.0000 1.0000
38.2000 40.0000 1.0000
38.2600 52.0000 1.0000
38.3200 52.0000 1.0000
38.3800 68.0000 1.0000
38.4400 72.0000 1.0000
38.5000 77.0000 1.0000
38.5600 81.0000 1.0000
38.6200 73.0000 1.0000
38.6800 83.0000 1.0000
38.7400 123.0000 1.0000
38.8000 136.0000 1.0000
38.8600 156.0000 1.0000
38.9200 175.0000 1.0000
38.9800 236.0000 1.0000
39.0400 330.0000 1.0000
39.1000 425.0000 1.0000
39.1600 586.0000 1.0000
39.2200 819.0000 1.0000
39.2800 1166.0000 1.0000
39.3400 1549.0000 1.0000
39.4000 1814.0000 1.0000
39.4600 1673.0000 1.0000
39.5200 1295.0000 1.0000
39.5800 936.0000 1.0000
39.6400 636.0000 1.0000
39.7000 442.0000 1.0000
39.7600 342.0000 1.0000
39.8200 255.0000 1.0000
39.8800 215.0000 1.0000
39.9400 155.0000 1.0000
40.0000 139.0000 1.0000
40.0600 124.0000 1.0000
40.1200 110.0000 1.0000
40.1800 99.0000 1.0000
40.2400 89.0000 1.0000
40.3000 83.0000 1.0000
40.3600 49.0000 1.0000
40.4200 72.0000 1.0000
40.4800 43.0000 1.0000
40.5400 46.0000 1.0000
40.6000 55.0000 1.0000
40.6600 42.0000 1.0000
40.7200 45.0000 1.0000
40.7800 38.0000 1.0000
40.8400 47.0000 1.0000
40.9000 45.0000 1.0000
40.9600 26.0000 1.0000
41.0200 31.0000 1.0000
41.0800 34.0000 1.0000
41.1400 31.0000 1.0000
41.2000 30.0000 1.0000
41.2600 33.0000 1.0000
41.3200 28.0000 1.0000
41.3800 35.0000 1.0000
41.4400 32.0000 1.0000
41.5000 25.0000 1.0000
41.5600 28.0000 1.0000
41.6200 25.0000 1.0000
41.6800 24.0000 1.0000
41.7400 33.0000 1.0000
41.8000 25.0000 1.0000
41.8600 24.0000 1.0000
41.9200 27.0000 1.0000
41.9800 24.0000 1.0000
42.0400 28.0000 1.0000
42.1000 32.0000 1.0000
42.1600 29.0000 1.0000
42.2200 30.0000 1.0000
42.2800 36.0000 1.0000
42.3400 46.0000 1.0000
42.4000 53.0000 1.0000
42.4600 64.0000 1.0000
42.5200 49.0000 1.0000
42.5800 43.0000 1.0000
42.6400 30.0000 1.0000
42.7000 33.0000 1.0000
42.7600 30.0000 1.0000
42.8200 39.0000 1.0000
42.8800 32.0000 1.0000
42.9400 36.0000 1.0000
43.0000 30.0000 1.0000
43.0600 28.0000 1.0000
43.1200 33.0000 1.0000
43.1800 24.0000 1.0000
43.2400 31.0000 1.0000
43.3000 36.0000 1.0000
43.3600 29.0000 1.0000
43.4200 28.0000 1.0000
43.4800 28.0000 1.0000
43.5400 26.0000 1.0000
43.6000 29.0000 1.0000
43.6600 33.0000 1.0000
43.7200 31.0000 1.0000
43.7800 28.0000 1.0000
43.8400 19.0000 1.0000
43.9000 32.0000 1.0000
43.9600 23.0000 1.0000
44.0200 32.0000 1.0000
44.0800 28.0000 1.0000
44.1400 32.0000 1.0000
44.2000 28.0000 1.0000
44.2600 32.0000 1.0000
44.3200 22.0000 1.0000
44.3800 36.0000 1.0000
44.4400 31.0000 1.0000
44.5000 32.0000 1.0000
44.5600 34.0000 1.0000
44.6200 26.0000 1.0000
44.6800 30.0000 1.0000
44.7400 20.0000 1.0000
44.8000 29.0000 1.0000
44.8600 27.0000 1.0000
44.9200 29.0000 1.0000
44.9800 43.0000 1.0000
45.0400 47.0000 1.0000
45.1000 76.0000 1.0000
45.1600 89.0000 1.0000
45.2200 68.0000 1.0000
45.2800 62.0000 1.0000
45.3400 32.0000 1.0000
45.4000 33.0000 1.0000
45.4600 23.0000 1.0000
45.5200 26.0000 1.0000
45.5800 24.0000 1.0000
45.6400 30.0000 1.0000
45.7000 25.0000 1.0000
45.7600 21.0000 1.0000
45.8200 31.0000 1.0000
45.8800 28.0000 1.0000
45.9400 22.0000 1.0000
46.0000 35.0000 1.0000
46.0600 37.0000 1.0000
46.1200 36.0000 1.0000
46.1800 44.0000 1.0000
46.2400 57.0000 1.0000
46.3000 52.0000 1.0000
46.3600 64.0000 1.0000
46.4200 41.0000 1.0000
46.4800 42.0000 1.0000
46.5400 29.0000 1.0000
46.6000 30.0000 1.0000
46.6600 34.0000 1.0000
46.7200 32.0000 1.0000
46.7800 34.0000 1.0000
46.8400 30.0000 1.0000
46.9000 33.0000 1.0000
46.9600 37.0000 1.0000
47.0200 43.0000 1.0000
47.0800 39.0000 1.0000
47.1400 57.0000 1.0000
47.2000 81.0000 1.0000
47.2600 63.0000 1.0000
47.3200 88.0000 1.0000
47.3800 98.0000 1.0000
47.4400 128.0000 1.0000
47.5000 147.0000 1.0000
47.5600 134.0000 1.0000
47.6200 154.0000 1.0000
47.6800 107.0000 1.0000
47.7400 81.0000 1.0000
47.8000 83.0000 1.0000
47.8600 77.0000 1.0000
47.9200 66.0000 1.0000
47.9800 56.0000 1.0000
48.0400 49.0000 1.0000
48.1000 38.0000 1.0000
48.1600 39.0000 1.0000
48.2200 33.0000 1.0000
48.2800 31.0000 1.0000
48.3400 42.0000 1.0000
48.4000 37.0000 1.0000
48.4600 33.0000 1.0000
48.5200 27.0000 1.0000
48.5800 38.0000 1.0000
48.6400 27.0000 1.0000
48.7000 26.0000 1.0000
48.7600 44.0000 1.0000
48.8200 34.0000 1.0000
48.8800 37.0000 1.0000
48.9400 39.0000 1.0000
49.0000 28.0000 1.0000
49.0600 24.0000 1.0000
49.1200 20.0000 1.0000
49.1800 37.0000 1.0000
49.2400 32.0000 1.0000
49.3000 27.0000 1.0000
49.3600 28.0000 1.0000
49.4200 26.0000 1.0000
49.4800 27.0000 1.0000
49.5400 27.0000 1.0000
49.6000 31.0000 1.0000
49.6600 35.0000 1.0000
49.7200 42.0000 1.0000
49.7800 35.0000 1.0000
49.8400 28.0000 1.0000
49.9000 28.0000 1.0000
49.9600 24.0000 1.0000
50.0200 25.0000 1.0000
50.0800 24.0000 1.0000
50.1400 20.0000 1.0000
50.2000 20.0000 1.0000
50.2600 25.0000 1.0000
50.3200 26.0000 1.0000
50.3800 31.0000 1.0000
50.4400 26.0000 1.0000
50.5000 25.0000 1.0000
50.5600 33.0000 1.0000
50.6200 28.0000 1.0000
50.6800 24.0000 1.0000
50.7400 23.0000 1.0000
50.8000 20.0000 1.0000
50.8600 24.0000 1.0000
50.9200 25.0000 1.0000
50.9800 26.0000 1.0000
51.0400 21.0000 1.0000
51.1000 25.0000 1.0000
51.1600 27.0000 1.0000
51.2200 27.0000 1.0000
51.2800 29.0000 1.0000
51.3400 19.0000 1.0000
51.4000 20.0000 1.0000
51.4600 31.0000 1.0000
51.5200 22.0000 1.0000
51.5800 23.0000 1.0000
51.6400 28.0000 1.0000
51.7000 43.0000 1.0000
51.7600 30.0000 1.0000
51.8200 31.0000 1.0000
51.8800 20.0000 1.0000
51.9400 24.0000 1.0000
52.0000 32.0000 1.0000
52.0600 29.0000 1.0000
52.1200 27.0000 1.0000
52.1800 35.0000 1.0000
52.2400 40.0000 1.0000
52.3000 51.0000 1.0000
52.3600 49.0000 1.0000
52.4200 39.0000 1.0000
52.4800 50.0000 1.0000
52.5400 50.0000 1.0000
52.6000 32.0000 1.0000
52.6600 37.0000 1.0000
52.7200 30.0000 1.0000
52.7800 23.0000 1.0000
52.8400 30.0000 1.0000
52.9000 35.0000 1.0000
52.9600 31.0000 1.0000
53.0200 47.0000 1.0000
53.0800 59.0000 1.0000
53.1400 70.0000 1.0000
53.2000 74.0000 1.0000
53.2600 45.0000 1.0000
53.3200 54.0000 1.0000
53.3800 33.0000 1.0000
53.4400 22.0000 1.0000
53.5000 34.0000 1.0000
53.5600 33.0000 1.0000
53.6200 23.0000 1.0000
53.6800 34.0000 1.0000
53.7400 40.0000 1.0000
53.8000 32.0000 1.0000
53.8600 33.0000 1.0000
53.9200 51.0000 1.0000
53.9800 60.0000 1.0000
54.0400 59.0000 1.0000
54.1000 68.0000 1.0000
54.1600 54.0000 1.0000
54.2200 56.0000 1.0000
54.2800 34.0000 1.0000
54.3400 48.0000 1.0000
54.4000 34.0000 1.0000
54.4600 32.0000 1.0000
54.5200 41.0000 1.0000
54.5800 46.0000 1.0000
54.6400 37.0000 1.0000
54.7000 39.0000 1.0000
54.7600 54.0000 1.0000
54.8200 61.0000 1.0000
54.8800 47.0000 1.0000
54.9400 60.0000 1.0000
55.0000 43.0000 1.0000
55.0600 47.0000 1.0000
55.1200 33.0000 1.0000
55.1800 50.0000 1.0000
55.2400 63.0000 1.0000
55.3000 54.0000 1.0000
55.3600 73.0000 1.0000
55.4200 77.0000 1.0000
55.4800 96.0000 1.0000
55.5400 122.0000 1.0000
55.6000 144.0000 1.0000
55.6600 167.0000 1.0000
55.7200 199.0000 1.0000
55.7800 290.0000 1.0000
55.8400 327.0000 1.0000
55.9000 335.0000 1.0000
55.9600 290.0000 1.0000
56.0200 287.0000 1.0000
56.0800 222.0000 1.0000
56.1400 166.0000 1.0000
56.2000 141.0000 1.0000
56.2600 113.0000 1.0000
56.3200 101.0000 1.0000
56.3800 80.0000 1.0000
56.4400 64.0000 1.0000
56.5000 56.0000 1.0000
56.5600 59.0000 1.0000
56.6200 54.0000 1.0000
56.6800 49.0000 1.0000
56.7400 53.0000 1.0000
56.8000 40.0000 1.0000
56.8600 54.0000 1.0000
56.9200 50.0000 1.0000
56.9800 39.0000 1.0000
57.0400 37.0000 1.0000
57.1000 35.0000 1.0000
57.1600 33.0000 1.0000
57.2200 50.0000 1.0000
57.2800 53.0000 1.0000
57.3400 51.0000 1.0000
57.4000 59.0000 1.0000
57.4600 55.0000 1.0000
57.5200 77.0000 1.0000
57.5800 64.0000 1.0000
57.6400 96.0000 1.0000
57.7000 90.0000 1.0000
57.7600 109.0000 1.0000
57.8200 139.0000 1.0000
57.8800 189.0000 1.0000
57.9400 205.0000 1.0000
58.0000 263.0000 1.0000
58.0600 279.0000 1.0000
58.1200 297.0000 1.0000
58.1800 309.0000 1.0000
58.2400 256.0000 1.0000
58.3000 239.0000 1.0000
58.3600 196.0000 1.0000
58.4200 178.0000 1.0000
58.4800 138.0000 1.0000
58.5400 107.0000 1.0000
58.6000 79.0000 1.0000
58.6600 71.0000 1.0000
58.7200 59.0000 1.0000
58.7800 49.0000 1.0000
58.8400 54.0000 1.0000
58.9000 54.0000 1.0000
58.9600 50.0000 1.0000
59.0200 44.0000 1.0000
59.0800 39.0000 1.0000
59.1400 47.0000 1.0000
59.2000 26.0000 1.0000
59.2600 42.0000 1.0000
59.3200 41.0000 1.0000
59.3800 41.0000 1.0000
59.4400 48.0000 1.0000
59.5000 38.0000 1.0000
59.5600 46.0000 1.0000
59.6200 46.0000 1.0000
59.6800 36.0000 1.0000
59.7400 38.0000 1.0000
59.8000 32.0000 1.0000
59.8600 46.0000 1.0000
59.9200 47.0000 1.0000
59.9800 41.0000 1.0000
60.0400 41.0000 1.0000
60.1000 36.0000 1.0000
60.1600 30.0000 1.0000
60.2200 41.0000 1.0000
60.2800 35.0000 1.0000
60.3400 46.0000 1.0000
60.4000 34.0000 1.0000
60.4600 34.0000 1.0000
60.5200 61.0000 1.0000
60.5800 49.0000 1.0000
60.6400 43.0000 1.0000
60.7000 55.0000 1.0000
60.7600 52.0000 1.0000
60.8200 62.0000 1.0000
60.8800 58.0000 1.0000
60.9400 67.0000 1.0000
61.0000 102.0000 1.0000
61.0600 129.0000 1.0000
61.1200 151.0000 1.0000
61.1800 191.0000 1.0000
61.2400 219.0000 1.0000
61.3000 281.0000 1.0000
61.3600 290.0000 1.0000
61.4200 258.0000 1.0000
61.4800 214.0000 1.0000
61.5400 197.0000 1.0000
61.6000 168.0000 1.0000
61.6600 94.0000 1.0000
61.7200 91.0000 1.0000
61.7800 108.0000 1.0000
61.8400 63.0000 1.0000
61.9000 62.0000 1.0000
61.9600 60.0000 1.0000
62.0200 54.0000 1.0000
62.0800 61.0000 1.0000
62.1400 43.0000 1.0000
62.2000 53.0000 1.0000
62.2600 41.0000 1.0000
62.3200 39.0000 1.0000
62.3800 31.0000 1.0000
62.4400 31.0000 1.0000
62.5000 35.0000 1.0000
62.5600 26.0000 1.0000
62.6200 34.0000 1.0000
62.6800 25.0000 1.0000
62.7400 40.0000 1.0000
62.8000 33.0000 1.0000
62.8600 29.0000 1.0000
62.9200 33.0000 1.0000
62.9800 31.0000 1.0000
63.0400 30.0000 1.0000
63.1000 28.0000 1.0000
63.1600 18.0000 1.0000
63.2200 32.0000 1.0000
63.2800 36.0000 1.0000
63.3400 30.0000 1.0000
63.4000 24.0000 1.0000
63.4600 29.0000 1.0000
63.5200 29.0000 1.0000
63.5800 41.0000 1.0000
63.6400 35.0000 1.0000
63.7000 29.0000 1.0000
63.7600 27.0000 1.0000
63.8200 19.0000 1.0000
63.8800 26.0000 1.0000
63.9400 26.0000 1.0000
64.0000 19.0000 1.0000
64.0600 31.0000 1.0000
64.1200 21.0000 1.0000
64.1800 33.0000 1.0000
64.2400 24.0000 1.0000
64.3000 25.0000 1.0000
64.3600 23.0000 1.0000
64.4200 21.0000 1.0000
64.4800 29.0000 1.0000
64.5400 31.0000 1.0000
64.6000 29.0000 1.0000
64.6600 31.0000 1.0000
64.7200 29.0000 1.0000
64.7800 34.0000 1.0000
64.8400 30.0000 1.0000
64.9000 51.0000 1.0000
64.9600 51.0000 1.0000
65.0200 39.0000 1.0000
65.0800 54.0000 1.0000
65.1400 86.0000 1.0000
65.2000 61.0000 1.0000
65.2600 87.0000 1.0000
65.3200 76.0000 1.0000
65.3800 106.0000 1.0000
65.4400 141.0000 1.0000
65.5000 132.0000 1.0000
65.5600 131.0000 1.0000
65.6200 142.0000 1.0000
65.6800 137.0000 1.0000
65.7400 116.0000 1.0000
65.8000 86.0000 1.0000
65.8600 80.0000 1.0000
65.9200 63.0000 1.0000
65.9800 66.0000 1.0000
66.0400 42.0000 1.0000
66.1000 39.0000 1.0000
66.1600 38.0000 1.0000
66.2200 49.0000 1.0000
66.2800 28.0000 1.0000
66.3400 31.0000 1.0000
66.4000 40.0000 1.0000
66.4600 30.0000 1.0000
66.5200 29.0000 1.0000
66.5800 23.0000 1.0000
66.6400 33.0000 1.0000
66.7000 26.0000 1.0000
66.7600 28.0000 1.0000
66.8200 24.0000 1.0000
66.8800 30.0000 1.0000
66.9400 31.0000 1.0000
67.0000 25.0000 1.0000
67.0600 28.0000 1.0000
67.1200 28.0000 1.0000
67.1800 28.0000 1.0000
67.2400 25.0000 1.0000
67.3000 28.0000 1.0000
67.3600 31.0000 1.0000
67.4200 26.0000 1.0000
67.4800 26.0000 1.0000
67.5400 28.0000 1.0000
67.6000 21.0000 1.0000
67.6600 28.0000 1.0000
67.7200 24.0000 1.0000
67.7800 28.0000 1.0000
67.8400 20.0000 1.0000
67.9000 26.0000 1.0000
67.9600 26.0000 1.0000
68.0200 23.0000 1.0000
68.0800 34.0000 1.0000
68.1400 23.0000 1.0000
68.2000 33.0000 1.0000
68.2600 23.0000 1.0000
68.3200 23.0000 1.0000
68.3800 22.0000 1.0000
68.4400 32.0000 1.0000
68.5000 26.0000 1.0000
68.5600 31.0000 1.0000
68.6200 39.0000 1.0000
68.6800 34.0000 1.0000
68.7400 32.0000 1.0000
68.8000 30.0000 1.0000
68.8600 36.0000 1.0000
68.9200 29.0000 1.0000
68.9800 31.0000 1.0000
69.0400 28.0000 1.0000
69.1000 35.0000 1.0000
69.1600 23.0000 1.0000
69.2200 31.0000 1.0000
69.2800 23.0000 1.0000
69.3400 32.0000 1.0000
69.4000 24.0000 1.0000
69.4600 26.0000 1.0000
69.5200 37.0000 1.0000
69.5800 16.0000 1.0000
69.6400 29.0000 1.0000
69.7000 41.0000 1.0000
69.7600 38.0000 1.0000
69.8200 39.0000 1.0000
69.8800 42.0000 1.0000
69.9400 47.0000 1.0000
70.0000 55.0000 1.0000
*RAS_INT_END
*RAS_DATA_END