File: Examples/data/HoMoC2.ras
*RAS_DATA_START
*RAS_HEADER_START
*DISP_FMT_X "%.2f"
*DISP_FMT_Y "%.0f"
*DISP_FULLSCALE "2658.0000000000"
*DISP_LINE_COLOR "255.0000000000"
*DISP_LINE_STYLE "0.0000000000"
*DISP_LINE_WIDTH "0.2500000000"
*DISP_NOTE "測定データ-1"
*DISP_OFFSET_Y "0.0000000000"
*DISP_PEAKSEARCH_UNIT_Y "cps"
*DISP_RANGE_BOTTOM "0.0000000000"
*DISP_RANGE_LEFT "10.0000000000"
*DISP_RANGE_LOGCUTOFF "0.0100000000"
*DISP_RANGE_RIGHT "70.0000000000"
*DISP_RANGE_TOP "2658.0000000000"
*DISP_SCALE_MODE_Y "0.0000000000"
*DISP_TAB_NAME "2θ/θ"
*DISP_TITLE_Y "強度"
*DISP_UNIT_Y "cps"
*DISP_WINDOW_NAME "MSG_MACROENGINE"
*FILE_COMMENT " "
*FILE_MD5 ""
*FILE_MEMO " "
*FILE_OPERATOR "Administrator"
*FILE_SAMPLE " "
*FILE_TYPE "RAS_RAW"
*FILE_USERGROUP "システムマネージャ"
*FILE_VERSION "1.0000000000"
*HW_ATTACHMENT_ID "ATT1025"
*HW_ATTACHMENT_NAME "標準試料台|Standard Sample Holder"
*HW_COUNTER_ID-0 "CUT0021"
*HW_COUNTER_ID-1 "CUT0020"
*HW_COUNTER_ID-2 "CUT0020"
*HW_COUNTER_ID-3 "CMC0021"
*HW_COUNTER_NAME-0 "SC-70|SC-70"
*HW_COUNTER_NAME-1 "None|None"
*HW_COUNTER_NAME-2 "None|None"
*HW_COUNTER_NAME-3 "検出器モノクロメータ|Detector monochromator"
*HW_COUNTER_SELECT_NAME "SC-70|SC-70"
*HW_ECP_HV "641.5000000000"
*HW_ECP_HV_UNIT "V"
*HW_GONIOMETER_ID "GON0070"
*HW_GONIOMETER_NAME "MiniFlex 300/600|MiniFlex 300/600"
*HW_GONIOMETER_RADIUS-0 "79.0"
*HW_GONIOMETER_RADIUS-1 "91.5"
*HW_GONIOMETER_RADIUS-2 "150.0"
*HW_GONIOMETER_RADIUS-3 "0"
*HW_GONIOMETER_RADIUS-4 "103.4"
*HW_GONIOMETER_RADIUS-5 "150.0"
*HW_GONIOMETER_RADIUS-6 "46.6"
*HW_GONIOMETER_RADIUS-7 "160.0"
*HW_I_OPT_ID-0 "ISL0021"
*HW_I_OPT_ID-1 "ISO0021"
*HW_I_OPT_NAME-0 "発散スリット|Divergence slit"
*HW_I_OPT_NAME-1 "入射平行スリット|Incident parallel slit"
*HW_R_ATTENUATER_AUTOMODE "0"
*HW_R_OPT_ID-0 "RSS0021"
*HW_R_OPT_ID-1 "RSO0021"
*HW_R_OPT_ID-2 "RRS0021"
*HW_R_OPT_NAME-0 "散乱スリット|Scattering slit"
*HW_R_OPT_NAME-1 "受光平行スリット|Receiving soller slit"
*HW_R_OPT_NAME-2 "受光スリット|Receiving slit"
*HW_SAMPLE_HOLDER_ID "SMP0000"
*HW_SAMPLE_HOLDER_NAME "無し|None"
*HW_XG_CURRENT_MAX "15"
*HW_XG_CURRENT_MIN "2"
*HW_XG_CURRENT_RESOLUTION "1"
*HW_XG_CURRENT_UNIT "mA"
*HW_XG_FOCUS "1mm x 10mm"
*HW_XG_FOCUS_TYPE "Normal"
*HW_XG_ID ""
*HW_XG_NAME "300W/600W 封入管-A|300W/600W Sealed tube-A"
*HW_XG_TARGET_ATOMIC_NUMBER "29.0000000000"
*HW_XG_TARGET_NAME "Cu"
*HW_XG_TYPE "Hermetic"
*HW_XG_VOLTAGE_MAX "40"
*HW_XG_VOLTAGE_MIN "20"
*HW_XG_VOLTAGE_RESOLUTION "1"
*HW_XG_VOLTAGE_UNIT "kV"
*HW_XG_WATT_MAX "1"
*HW_XG_WATT_UNIT "kW"
*HW_XG_WAVE_LENGTH_ALPHA1 "1.540593"
*HW_XG_WAVE_LENGTH_ALPHA2 "1.544414"
*HW_XG_WAVE_LENGTH_BETA "1.392250"
*MEAS_COND_AXIS_NAME-0 "2θ/θ"
*MEAS_COND_AXIS_NAME-1 "Soller(inc.)"
*MEAS_COND_AXIS_NAME-2 "IHS"
*MEAS_COND_AXIS_NAME-3 "DS"
*MEAS_COND_AXIS_NAME-4 "SS"
*MEAS_COND_AXIS_NAME-5 "Soller(rec.)"
*MEAS_COND_AXIS_NAME-6 "RS"
*MEAS_COND_AXIS_NAME-7 "フィルター"
*MEAS_COND_AXIS_NAME-8 "モノクロメータ"
*MEAS_COND_AXIS_NAME-9 "HV"
*MEAS_COND_AXIS_NAME-10 "PHA"
*MEAS_COND_AXIS_NAME_INTERNAL-0 "TwoThetaTheta"
*MEAS_COND_AXIS_NAME_INTERNAL-1 "IncidentSollerSlit"
*MEAS_COND_AXIS_NAME_INTERNAL-2 "IncidentAxdSlit"
*MEAS_COND_AXIS_NAME_INTERNAL-3 "IncidentSlitBox"
*MEAS_COND_AXIS_NAME_INTERNAL-4 "ReceivingSlitBox1"
*MEAS_COND_AXIS_NAME_INTERNAL-5 "ReceivingSollerSlit"
*MEAS_COND_AXIS_NAME_INTERNAL-6 "ReceivingSlitBox2"
*MEAS_COND_AXIS_NAME_INTERNAL-7 "Filter"
*MEAS_COND_AXIS_NAME_INTERNAL-8 "CounterMonochromator"
*MEAS_COND_AXIS_NAME_INTERNAL-9 "HV"
*MEAS_COND_AXIS_NAME_INTERNAL-10 "PHA"
*MEAS_COND_AXIS_NAME_MAGICNO-0 "268632064.0000000000"
*MEAS_COND_AXIS_NAME_MAGICNO-1 "20971521.0000000000"
*MEAS_COND_AXIS_NAME_MAGICNO-2 "22020097.0000000000"
*MEAS_COND_AXIS_NAME_MAGICNO-3 "22020097.0000000000"
*MEAS_COND_AXIS_NAME_MAGICNO-4 "23068673.0000000000"
*MEAS_COND_AXIS_NAME_MAGICNO-5 "20971521.0000000000"
*MEAS_COND_AXIS_NAME_MAGICNO-6 "23068673.0000000000"
*MEAS_COND_AXIS_NAME_MAGICNO-7 "20971521.0000000000"
*MEAS_COND_AXIS_NAME_MAGICNO-8 "20971521.0000000000"
*MEAS_COND_AXIS_NAME_MAGICNO-9 "0.0000000000"
*MEAS_COND_AXIS_NAME_MAGICNO-10 "0.0000000000"
*MEAS_COND_AXIS_OFFSET-0 "0.0000000000"
*MEAS_COND_AXIS_OFFSET-1 "-"
*MEAS_COND_AXIS_OFFSET-2 "-"
*MEAS_COND_AXIS_OFFSET-3 "-"
*MEAS_COND_AXIS_OFFSET-4 "-"
*MEAS_COND_AXIS_OFFSET-5 "-"
*MEAS_COND_AXIS_OFFSET-6 "-"
*MEAS_COND_AXIS_OFFSET-7 "-"
*MEAS_COND_AXIS_OFFSET-8 "-"
*MEAS_COND_AXIS_OFFSET-9 "-"
*MEAS_COND_AXIS_OFFSET-10 "-"
*MEAS_COND_AXIS_POSITION-0 "10.0000000000"
*MEAS_COND_AXIS_POSITION-1 "5.0deg"
*MEAS_COND_AXIS_POSITION-2 "10.0mm"
*MEAS_COND_AXIS_POSITION-3 "1.250deg"
*MEAS_COND_AXIS_POSITION-4 "1.250deg"
*MEAS_COND_AXIS_POSITION-5 "5.0deg"
*MEAS_COND_AXIS_POSITION-6 "0.3mm"
*MEAS_COND_AXIS_POSITION-7 "None"
*MEAS_COND_AXIS_POSITION-8 "Bent"
*MEAS_COND_AXIS_POSITION-9 "641.5000000000"
*MEAS_COND_AXIS_POSITION-10 "566.2500000000"
*MEAS_COND_AXIS_UNIT-0 "deg"
*MEAS_COND_AXIS_UNIT-1 ""
*MEAS_COND_AXIS_UNIT-2 ""
*MEAS_COND_AXIS_UNIT-3 ""
*MEAS_COND_AXIS_UNIT-4 ""
*MEAS_COND_AXIS_UNIT-5 ""
*MEAS_COND_AXIS_UNIT-6 ""
*MEAS_COND_AXIS_UNIT-7 ""
*MEAS_COND_AXIS_UNIT-8 ""
*MEAS_COND_AXIS_UNIT-9 "V"
*MEAS_COND_AXIS_UNIT-10 "mV"
*MEAS_COND_COUNTER_CNTLOSS_CORR "0.0000000000"
*MEAS_COND_COUNTER_PHABASE "566.2500000000"
*MEAS_COND_COUNTER_PHAWINDOW "878.7500000000"
*MEAS_COND_COUNTER_PHA_UNIT "mV"
*MEAS_COND_COUNTER_TAUDIFF "0.2500000000"
*MEAS_COND_COUNTER_TAUINT "0.7500000000"
*MEAS_COND_IRRADIATION_MODE "OFF"
*MEAS_COND_IRRADIATION_WIDTH ""
*MEAS_COND_OPT_ATTR " "
*MEAS_COND_OPT_NAME ""
*MEAS_COND_UNSYMMETRIC_MODE "OFF"
*MEAS_COND_XG_CURRENT "15.0000000000"
*MEAS_COND_XG_VOLTAGE "40.0000000000"
*MEAS_COND_XG_WAVE_TYPE "Ka"
*MEAS_DATA_COUNT "3001.0000000000"
*MEAS_SCAN_AXIS_X "2θ/θ"
*MEAS_SCAN_AXIS_X_INTERNAL "TwoThetaTheta"
*MEAS_SCAN_END_TIME "10/02/20 13:04:06"
*MEAS_SCAN_MODE "CONTINUOUS"
*MEAS_SCAN_MONITOR "0"
*MEAS_SCAN_RESOLUTION_X "0.0025"
*MEAS_SCAN_SPEED "2.0000"
*MEAS_SCAN_SPEED_UNIT "deg/min"
*MEAS_SCAN_START "10.0000000000"
*MEAS_SCAN_START_TIME "10/02/20 12:33:56"
*MEAS_SCAN_STEP "0.0200000000"
*MEAS_SCAN_STOP "70.0000000000"
*MEAS_SCAN_UNIT_X "deg"
*MEAS_SCAN_UNIT_Y "counts"
*SLIT_SYSTEM "0"
*RAS_HEADER_END
*RAS_INT_START
10.0000 40.0000 1.0000
10.0600 48.0000 1.0000
10.1200 52.0000 1.0000
10.1800 47.0000 1.0000
10.2400 53.0000 1.0000
10.3000 50.0000 1.0000
10.3600 43.0000 1.0000
10.4200 45.0000 1.0000
10.4800 57.0000 1.0000
10.5400 56.0000 1.0000
10.6000 38.0000 1.0000
10.6600 50.0000 1.0000
10.7200 56.0000 1.0000
10.7800 45.0000 1.0000
10.8400 46.0000 1.0000
10.9000 53.0000 1.0000
10.9600 42.0000 1.0000
11.0200 46.0000 1.0000
11.0800 61.0000 1.0000
11.1400 56.0000 1.0000
11.2000 54.0000 1.0000
11.2600 32.0000 1.0000
11.3200 45.0000 1.0000
11.3800 48.0000 1.0000
11.4400 41.0000 1.0000
11.5000 54.0000 1.0000
11.5600 50.0000 1.0000
11.6200 50.0000 1.0000
11.6800 52.0000 1.0000
11.7400 42.0000 1.0000
11.8000 46.0000 1.0000
11.8600 46.0000 1.0000
11.9200 41.0000 1.0000
11.9800 55.0000 1.0000
12.0400 52.0000 1.0000
12.1000 59.0000 1.0000
12.1600 51.0000 1.0000
12.2200 54.0000 1.0000
12.2800 55.0000 1.0000
12.3400 51.0000 1.0000
12.4000 57.0000 1.0000
12.4600 67.0000 1.0000
12.5200 47.0000 1.0000
12.5800 53.0000 1.0000
12.6400 49.0000 1.0000
12.7000 56.0000 1.0000
12.7600 47.0000 1.0000
12.8200 58.0000 1.0000
12.8800 55.0000 1.0000
12.9400 52.0000 1.0000
13.0000 41.0000 1.0000
13.0600 43.0000 1.0000
13.1200 49.0000 1.0000
13.1800 47.0000 1.0000
13.2400 44.0000 1.0000
13.3000 67.0000 1.0000
13.3600 62.0000 1.0000
13.4200 65.0000 1.0000
13.4800 65.0000 1.0000
13.5400 64.0000 1.0000
13.6000 66.0000 1.0000
13.6600 64.0000 1.0000
13.7200 51.0000 1.0000
13.7800 59.0000 1.0000
13.8400 46.0000 1.0000
13.9000 59.0000 1.0000
13.9600 64.0000 1.0000
14.0200 69.0000 1.0000
14.0800 54.0000 1.0000
14.1400 55.0000 1.0000
14.2000 67.0000 1.0000
14.2600 55.0000 1.0000
14.3200 84.0000 1.0000
14.3800 75.0000 1.0000
14.4400 57.0000 1.0000
14.5000 60.0000 1.0000
14.5600 51.0000 1.0000
14.6200 55.0000 1.0000
14.6800 59.0000 1.0000
14.7400 66.0000 1.0000
14.8000 60.0000 1.0000
14.8600 66.0000 1.0000
14.9200 62.0000 1.0000
14.9800 63.0000 1.0000
15.0400 64.0000 1.0000
15.1000 57.0000 1.0000
15.1600 63.0000 1.0000
15.2200 67.0000 1.0000
15.2800 53.0000 1.0000
15.3400 59.0000 1.0000
15.4000 53.0000 1.0000
15.4600 72.0000 1.0000
15.5200 66.0000 1.0000
15.5800 62.0000 1.0000
15.6400 62.0000 1.0000
15.7000 73.0000 1.0000
15.7600 64.0000 1.0000
15.8200 47.0000 1.0000
15.8800 60.0000 1.0000
15.9400 64.0000 1.0000
16.0000 67.0000 1.0000
16.0600 59.0000 1.0000
16.1200 65.0000 1.0000
16.1800 60.0000 1.0000
16.2400 81.0000 1.0000
16.3000 61.0000 1.0000
16.3600 88.0000 1.0000
16.4200 60.0000 1.0000
16.4800 63.0000 1.0000
16.5400 80.0000 1.0000
16.6000 66.0000 1.0000
16.6600 86.0000 1.0000
16.7200 75.0000 1.0000
16.7800 64.0000 1.0000
16.8400 68.0000 1.0000
16.9000 51.0000 1.0000
16.9600 62.0000 1.0000
17.0200 78.0000 1.0000
17.0800 74.0000 1.0000
17.1400 76.0000 1.0000
17.2000 90.0000 1.0000
17.2600 67.0000 1.0000
17.3200 69.0000 1.0000
17.3800 61.0000 1.0000
17.4400 83.0000 1.0000
17.5000 63.0000 1.0000
17.5600 75.0000 1.0000
17.6200 56.0000 1.0000
17.6800 85.0000 1.0000
17.7400 87.0000 1.0000
17.8000 85.0000 1.0000
17.8600 69.0000 1.0000
17.9200 84.0000 1.0000
17.9800 66.0000 1.0000
18.0400 78.0000 1.0000
18.1000 72.0000 1.0000
18.1600 80.0000 1.0000
18.2200 78.0000 1.0000
18.2800 69.0000 1.0000
18.3400 71.0000 1.0000
18.4000 80.0000 1.0000
18.4600 98.0000 1.0000
18.5200 82.0000 1.0000
18.5800 72.0000 1.0000
18.6400 61.0000 1.0000
18.7000 70.0000 1.0000
18.7600 88.0000 1.0000
18.8200 80.0000 1.0000
18.8800 71.0000 1.0000
18.9400 78.0000 1.0000
19.0000 78.0000 1.0000
19.0600 78.0000 1.0000
19.1200 77.0000 1.0000
19.1800 83.0000 1.0000
19.2400 72.0000 1.0000
19.3000 83.0000 1.0000
19.3600 66.0000 1.0000
19.4200 77.0000 1.0000
19.4800 90.0000 1.0000
19.5400 88.0000 1.0000
19.6000 102.0000 1.0000
19.6600 89.0000 1.0000
19.7200 79.0000 1.0000
19.7800 87.0000 1.0000
19.8400 81.0000 1.0000
19.9000 100.0000 1.0000
19.9600 97.0000 1.0000
20.0200 89.0000 1.0000
20.0800 90.0000 1.0000
20.1400 98.0000 1.0000
20.2000 88.0000 1.0000
20.2600 104.0000 1.0000
20.3200 91.0000 1.0000
20.3800 83.0000 1.0000
20.4400 98.0000 1.0000
20.5000 107.0000 1.0000
20.5600 81.0000 1.0000
20.6200 105.0000 1.0000
20.6800 99.0000 1.0000
20.7400 93.0000 1.0000
20.8000 91.0000 1.0000
20.8600 100.0000 1.0000
20.9200 92.0000 1.0000
20.9800 93.0000 1.0000
21.0400 99.0000 1.0000
21.1000 77.0000 1.0000
21.1600 102.0000 1.0000
21.2200 89.0000 1.0000
21.2800 85.0000 1.0000
21.3400 105.0000 1.0000
21.4000 92.0000 1.0000
21.4600 95.0000 1.0000
21.5200 93.0000 1.0000
21.5800 81.0000 1.0000
21.6400 96.0000 1.0000
21.7000 82.0000 1.0000
21.7600 105.0000 1.0000
21.8200 106.0000 1.0000
21.8800 105.0000 1.0000
21.9400 99.0000 1.0000
22.0000 107.0000 1.0000
22.0600 108.0000 1.0000
22.1200 79.0000 1.0000
22.1800 95.0000 1.0000
22.2400 108.0000 1.0000
22.3000 105.0000 1.0000
22.3600 89.0000 1.0000
22.4200 100.0000 1.0000
22.4800 107.0000 1.0000
22.5400 100.0000 1.0000
22.6000 99.0000 1.0000
22.6600 97.0000 1.0000
22.7200 97.0000 1.0000
22.7800 104.0000 1.0000
22.8400 130.0000 1.0000
22.9000 99.0000 1.0000
22.9600 109.0000 1.0000
23.0200 98.0000 1.0000
23.0800 104.0000 1.0000
23.1400 98.0000 1.0000
23.2000 104.0000 1.0000
23.2600 105.0000 1.0000
23.3200 93.0000 1.0000
23.3800 115.0000 1.0000
23.4400 101.0000 1.0000
23.5000 101.0000 1.0000
23.5600 104.0000 1.0000
23.6200 94.0000 1.0000
23.6800 102.0000 1.0000
23.7400 113.0000 1.0000
23.8000 112.0000 1.0000
23.8600 103.0000 1.0000
23.9200 102.0000 1.0000
23.9800 102.0000 1.0000
24.0400 101.0000 1.0000
24.1000 107.0000 1.0000
24.1600 117.0000 1.0000
24.2200 80.0000 1.0000
24.2800 99.0000 1.0000
24.3400 125.0000 1.0000
24.4000 100.0000 1.0000
24.4600 90.0000 1.0000
24.5200 117.0000 1.0000
24.5800 100.0000 1.0000
24.6400 107.0000 1.0000
24.7000 82.0000 1.0000
24.7600 105.0000 1.0000
24.8200 86.0000 1.0000
24.8800 93.0000 1.0000
24.9400 113.0000 1.0000
25.0000 105.0000 1.0000
25.0600 122.0000 1.0000
25.1200 103.0000 1.0000
25.1800 108.0000 1.0000
25.2400 105.0000 1.0000
25.3000 113.0000 1.0000
25.3600 97.0000 1.0000
25.4200 136.0000 1.0000
25.4800 102.0000 1.0000
25.5400 106.0000 1.0000
25.6000 109.0000 1.0000
25.6600 124.0000 1.0000
25.7200 100.0000 1.0000
25.7800 112.0000 1.0000
25.8400 115.0000 1.0000
25.9000 131.0000 1.0000
25.9600 108.0000 1.0000
26.0200 112.0000 1.0000
26.0800 109.0000 1.0000
26.1400 121.0000 1.0000
26.2000 105.0000 1.0000
26.2600 115.0000 1.0000
26.3200 122.0000 1.0000
26.3800 97.0000 1.0000
26.4400 114.0000 1.0000
26.5000 115.0000 1.0000
26.5600 118.0000 1.0000
26.6200 108.0000 1.0000
26.6800 120.0000 1.0000
26.7400 119.0000 1.0000
26.8000 105.0000 1.0000
26.8600 125.0000 1.0000
26.9200 121.0000 1.0000
26.9800 113.0000 1.0000
27.0400 127.0000 1.0000
27.1000 98.0000 1.0000
27.1600 128.0000 1.0000
27.2200 129.0000 1.0000
27.2800 126.0000 1.0000
27.3400 109.0000 1.0000
27.4000 138.0000 1.0000
27.4600 132.0000 1.0000
27.5200 126.0000 1.0000
27.5800 116.0000 1.0000
27.6400 111.0000 1.0000
27.7000 124.0000 1.0000
27.7600 125.0000 1.0000
27.8200 147.0000 1.0000
27.8800 137.0000 1.0000
27.9400 126.0000 1.0000
28.0000 136.0000 1.0000
28.0600 116.0000 1.0000
28.1200 153.0000 1.0000
28.1800 147.0000 1.0000
28.2400 162.0000 1.0000
28.3000 162.0000 1.0000
28.3600 188.0000 1.0000
28.4200 189.0000 1.0000
28.4800 235.0000 1.0000
28.5400 248.0000 1.0000
28.6000 195.0000 1.0000
28.6600 174.0000 1.0000
28.7200 144.0000 1.0000
28.7800 160.0000 1.0000
28.8400 138.0000 1.0000
28.9000 143.0000 1.0000
28.9600 143.0000 1.0000
29.0200 141.0000 1.0000
29.0800 145.0000 1.0000
29.1400 159.0000 1.0000
29.2000 175.0000 1.0000
29.2600 182.0000 1.0000
29.3200 196.0000 1.0000
29.3800 235.0000 1.0000
29.4400 199.0000 1.0000
29.5000 183.0000 1.0000
29.5600 166.0000 1.0000
29.6200 139.0000 1.0000
29.6800 160.0000 1.0000
29.7400 142.0000 1.0000
29.8000 136.0000 1.0000
29.8600 125.0000 1.0000
29.9200 130.0000 1.0000
29.9800 129.0000 1.0000
30.0400 135.0000 1.0000
30.1000 142.0000 1.0000
30.1600 132.0000 1.0000
30.2200 139.0000 1.0000
30.2800 133.0000 1.0000
30.3400 139.0000 1.0000
30.4000 146.0000 1.0000
30.4600 105.0000 1.0000
30.5200 128.0000 1.0000
30.5800 103.0000 1.0000
30.6400 139.0000 1.0000
30.7000 132.0000 1.0000
30.7600 137.0000 1.0000
30.8200 110.0000 1.0000
30.8800 126.0000 1.0000
30.9400 114.0000 1.0000
31.0000 113.0000 1.0000
31.0600 104.0000 1.0000
31.1200 115.0000 1.0000
31.1800 121.0000 1.0000
31.2400 124.0000 1.0000
31.3000 126.0000 1.0000
31.3600 129.0000 1.0000
31.4200 149.0000 1.0000
31.4800 143.0000 1.0000
31.5400 120.0000 1.0000
31.6000 128.0000 1.0000
31.6600 135.0000 1.0000
31.7200 157.0000 1.0000
31.7800 161.0000 1.0000
31.8400 118.0000 1.0000
31.9000 129.0000 1.0000
31.9600 159.0000 1.0000
32.0200 161.0000 1.0000
32.0800 209.0000 1.0000
32.1400 221.0000 1.0000
32.2000 198.0000 1.0000
32.2600 150.0000 1.0000
32.3200 114.0000 1.0000
32.3800 111.0000 1.0000
32.4400 107.0000 1.0000
32.5000 102.0000 1.0000
32.5600 114.0000 1.0000
32.6200 116.0000 1.0000
32.6800 136.0000 1.0000
32.7400 193.0000 1.0000
32.8000 238.0000 1.0000
32.8600 281.0000 1.0000
32.9200 248.0000 1.0000
32.9800 203.0000 1.0000
33.0400 240.0000 1.0000
33.1000 291.0000 1.0000
33.1600 305.0000 1.0000
33.2200 218.0000 1.0000
33.2800 160.0000 1.0000
33.3400 117.0000 1.0000
33.4000 92.0000 1.0000
33.4600 97.0000 1.0000
33.5200 84.0000 1.0000
33.5800 82.0000 1.0000
33.6400 71.0000 1.0000
33.7000 89.0000 1.0000
33.7600 89.0000 1.0000
33.8200 92.0000 1.0000
33.8800 101.0000 1.0000
33.9400 104.0000 1.0000
34.0000 94.0000 1.0000
34.0600 100.0000 1.0000
34.1200 117.0000 1.0000
34.1800 171.0000 1.0000
34.2400 260.0000 1.0000
34.3000 290.0000 1.0000
34.3600 271.0000 1.0000
34.4200 192.0000 1.0000
34.4800 156.0000 1.0000
34.5400 108.0000 1.0000
34.6000 126.0000 1.0000
34.6600 124.0000 1.0000
34.7200 146.0000 1.0000
34.7800 154.0000 1.0000
34.8400 145.0000 1.0000
34.9000 137.0000 1.0000
34.9600 131.0000 1.0000
35.0200 147.0000 1.0000
35.0800 153.0000 1.0000
35.1400 310.0000 1.0000
35.2000 506.0000 1.0000
35.2600 751.0000 1.0000
35.3200 659.0000 1.0000
35.3800 516.0000 1.0000
35.4400 294.0000 1.0000
35.5000 161.0000 1.0000
35.5600 121.0000 1.0000
35.6200 87.0000 1.0000
35.6800 117.0000 1.0000
35.7400 87.0000 1.0000
35.8000 84.0000 1.0000
35.8600 89.0000 1.0000
35.9200 96.0000 1.0000
35.9800 73.0000 1.0000
36.0400 86.0000 1.0000
36.1000 60.0000 1.0000
36.1600 74.0000 1.0000
36.2200 76.0000 1.0000
36.2800 84.0000 1.0000
36.3400 90.0000 1.0000
36.4000 100.0000 1.0000
36.4600 91.0000 1.0000
36.5200 72.0000 1.0000
36.5800 102.0000 1.0000
36.6400 78.0000 1.0000
36.7000 72.0000 1.0000
36.7600 80.0000 1.0000
36.8200 82.0000 1.0000
36.8800 101.0000 1.0000
36.9400 87.0000 1.0000
37.0000 77.0000 1.0000
37.0600 83.0000 1.0000
37.1200 77.0000 1.0000
37.1800 79.0000 1.0000
37.2400 80.0000 1.0000
37.3000 76.0000 1.0000
37.3600 75.0000 1.0000
37.4200 68.0000 1.0000
37.4800 83.0000 1.0000
37.5400 81.0000 1.0000
37.6000 72.0000 1.0000
37.6600 96.0000 1.0000
37.7200 97.0000 1.0000
37.7800 143.0000 1.0000
37.8400 279.0000 1.0000
37.9000 354.0000 1.0000
37.9600 313.0000 1.0000
38.0200 201.0000 1.0000
38.0800 117.0000 1.0000
38.1400 86.0000 1.0000
38.2000 91.0000 1.0000
38.2600 73.0000 1.0000
38.3200 67.0000 1.0000
38.3800 54.0000 1.0000
38.4400 87.0000 1.0000
38.5000 71.0000 1.0000
38.5600 72.0000 1.0000
38.6200 61.0000 1.0000
38.6800 81.0000 1.0000
38.7400 75.0000 1.0000
38.8000 114.0000 1.0000
38.8600 95.0000 1.0000
38.9200 81.0000 1.0000
38.9800 113.0000 1.0000
39.0400 88.0000 1.0000
39.1000 115.0000 1.0000
39.1600 160.0000 1.0000
39.2200 332.0000 1.0000
39.2800 784.0000 1.0000
39.3400 1290.0000 1.0000
39.4000 1260.0000 1.0000
39.4600 911.0000 1.0000
39.5200 495.0000 1.0000
39.5800 220.0000 1.0000
39.6400 124.0000 1.0000
39.7000 105.0000 1.0000
39.7600 105.0000 1.0000
39.8200 101.0000 1.0000
39.8800 108.0000 1.0000
39.9400 136.0000 1.0000
40.0000 154.0000 1.0000
40.0600 165.0000 1.0000
40.1200 132.0000 1.0000
40.1800 133.0000 1.0000
40.2400 99.0000 1.0000
40.3000 80.0000 1.0000
40.3600 84.0000 1.0000
40.4200 97.0000 1.0000
40.4800 105.0000 1.0000
40.5400 132.0000 1.0000
40.6000 172.0000 1.0000
40.6600 192.0000 1.0000
40.7200 157.0000 1.0000
40.7800 125.0000 1.0000
40.8400 109.0000 1.0000
40.9000 72.0000 1.0000
40.9600 76.0000 1.0000
41.0200 69.0000 1.0000
41.0800 90.0000 1.0000
41.1400 67.0000 1.0000
41.2000 78.0000 1.0000
41.2600 61.0000 1.0000
41.3200 67.0000 1.0000
41.3800 69.0000 1.0000
41.4400 78.0000 1.0000
41.5000 66.0000 1.0000
41.5600 74.0000 1.0000
41.6200 68.0000 1.0000
41.6800 76.0000 1.0000
41.7400 70.0000 1.0000
41.8000 87.0000 1.0000
41.8600 80.0000 1.0000
41.9200 85.0000 1.0000
41.9800 85.0000 1.0000
42.0400 71.0000 1.0000
42.1000 71.0000 1.0000
42.1600 77.0000 1.0000
42.2200 79.0000 1.0000
42.2800 91.0000 1.0000
42.3400 74.0000 1.0000
42.4000 67.0000 1.0000
42.4600 82.0000 1.0000
42.5200 82.0000 1.0000
42.5800 78.0000 1.0000
42.6400 54.0000 1.0000
42.7000 75.0000 1.0000
42.7600 75.0000 1.0000
42.8200 74.0000 1.0000
42.8800 83.0000 1.0000
42.9400 60.0000 1.0000
43.0000 70.0000 1.0000
43.0600 59.0000 1.0000
43.1200 61.0000 1.0000
43.1800 65.0000 1.0000
43.2400 81.0000 1.0000
43.3000 64.0000 1.0000
43.3600 79.0000 1.0000
43.4200 73.0000 1.0000
43.4800 61.0000 1.0000
43.5400 66.0000 1.0000
43.6000 84.0000 1.0000
43.6600 76.0000 1.0000
43.7200 85.0000 1.0000
43.7800 83.0000 1.0000
43.8400 74.0000 1.0000
43.9000 64.0000 1.0000
43.9600 71.0000 1.0000
44.0200 76.0000 1.0000
44.0800 62.0000 1.0000
44.1400 61.0000 1.0000
44.2000 63.0000 1.0000
44.2600 69.0000 1.0000
44.3200 68.0000 1.0000
44.3800 61.0000 1.0000
44.4400 72.0000 1.0000
44.5000 69.0000 1.0000
44.5600 69.0000 1.0000
44.6200 77.0000 1.0000
44.6800 67.0000 1.0000
44.7400 82.0000 1.0000
44.8000 90.0000 1.0000
44.8600 61.0000 1.0000
44.9200 70.0000 1.0000
44.9800 89.0000 1.0000
45.0400 92.0000 1.0000
45.1000 63.0000 1.0000
45.1600 84.0000 1.0000
45.2200 72.0000 1.0000
45.2800 78.0000 1.0000
45.3400 84.0000 1.0000
45.4000 86.0000 1.0000
45.4600 86.0000 1.0000
45.5200 73.0000 1.0000
45.5800 63.0000 1.0000
45.6400 92.0000 1.0000
45.7000 77.0000 1.0000
45.7600 89.0000 1.0000
45.8200 84.0000 1.0000
45.8800 86.0000 1.0000
45.9400 87.0000 1.0000
46.0000 106.0000 1.0000
46.0600 102.0000 1.0000
46.1200 103.0000 1.0000
46.1800 95.0000 1.0000
46.2400 86.0000 1.0000
46.3000 95.0000 1.0000
46.3600 76.0000 1.0000
46.4200 100.0000 1.0000
46.4800 112.0000 1.0000
46.5400 119.0000 1.0000
46.6000 116.0000 1.0000
46.6600 114.0000 1.0000
46.7200 92.0000 1.0000
46.7800 66.0000 1.0000
46.8400 79.0000 1.0000
46.9000 75.0000 1.0000
46.9600 80.0000 1.0000
47.0200 76.0000 1.0000
47.0800 68.0000 1.0000
47.1400 71.0000 1.0000
47.2000 67.0000 1.0000
47.2600 65.0000 1.0000
47.3200 76.0000 1.0000
47.3800 91.0000 1.0000
47.4400 67.0000 1.0000
47.5000 84.0000 1.0000
47.5600 59.0000 1.0000
47.6200 64.0000 1.0000
47.6800 86.0000 1.0000
47.7400 78.0000 1.0000
47.8000 68.0000 1.0000
47.8600 91.0000 1.0000
47.9200 74.0000 1.0000
47.9800 80.0000 1.0000
48.0400 69.0000 1.0000
48.1000 80.0000 1.0000
48.1600 78.0000 1.0000
48.2200 80.0000 1.0000
48.2800 70.0000 1.0000
48.3400 77.0000 1.0000
48.4000 73.0000 1.0000
48.4600 79.0000 1.0000
48.5200 66.0000 1.0000
48.5800 70.0000 1.0000
48.6400 73.0000 1.0000
48.7000 76.0000 1.0000
48.7600 77.0000 1.0000
48.8200 77.0000 1.0000
48.8800 72.0000 1.0000
48.9400 85.0000 1.0000
49.0000 97.0000 1.0000
49.0600 68.0000 1.0000
49.1200 93.0000 1.0000
49.1800 91.0000 1.0000
49.2400 90.0000 1.0000
49.3000 69.0000 1.0000
49.3600 73.0000 1.0000
49.4200 78.0000 1.0000
49.4800 89.0000 1.0000
49.5400 79.0000 1.0000
49.6000 78.0000 1.0000
49.6600 67.0000 1.0000
49.7200 88.0000 1.0000
49.7800 78.0000 1.0000
49.8400 97.0000 1.0000
49.9000 108.0000 1.0000
49.9600 83.0000 1.0000
50.0200 96.0000 1.0000
50.0800 104.0000 1.0000
50.1400 98.0000 1.0000
50.2000 94.0000 1.0000
50.2600 138.0000 1.0000
50.3200 106.0000 1.0000
50.3800 91.0000 1.0000
50.4400 81.0000 1.0000
50.5000 82.0000 1.0000
50.5600 75.0000 1.0000
50.6200 68.0000 1.0000
50.6800 73.0000 1.0000
50.7400 80.0000 1.0000
50.8000 67.0000 1.0000
50.8600 71.0000 1.0000
50.9200 91.0000 1.0000
50.9800 67.0000 1.0000
51.0400 86.0000 1.0000
51.1000 80.0000 1.0000
51.1600 88.0000 1.0000
51.2200 88.0000 1.0000
51.2800 82.0000 1.0000
51.3400 75.0000 1.0000
51.4000 105.0000 1.0000
51.4600 88.0000 1.0000
51.5200 98.0000 1.0000
51.5800 106.0000 1.0000
51.6400 109.0000 1.0000
51.7000 84.0000 1.0000
51.7600 98.0000 1.0000
51.8200 91.0000 1.0000
51.8800 88.0000 1.0000
51.9400 130.0000 1.0000
52.0000 196.0000 1.0000
52.0600 313.0000 1.0000
52.1200 336.0000 1.0000
52.1800 248.0000 1.0000
52.2400 201.0000 1.0000
52.3000 150.0000 1.0000
52.3600 93.0000 1.0000
52.4200 87.0000 1.0000
52.4800 90.0000 1.0000
52.5400 78.0000 1.0000
52.6000 67.0000 1.0000
52.6600 66.0000 1.0000
52.7200 76.0000 1.0000
52.7800 71.0000 1.0000
52.8400 95.0000 1.0000
52.9000 99.0000 1.0000
52.9600 100.0000 1.0000
53.0200 107.0000 1.0000
53.0800 90.0000 1.0000
53.1400 96.0000 1.0000
53.2000 78.0000 1.0000
53.2600 102.0000 1.0000
53.3200 79.0000 1.0000
53.3800 72.0000 1.0000
53.4400 92.0000 1.0000
53.5000 97.0000 1.0000
53.5600 79.0000 1.0000
53.6200 72.0000 1.0000
53.6800 60.0000 1.0000
53.7400 61.0000 1.0000
53.8000 75.0000 1.0000
53.8600 69.0000 1.0000
53.9200 85.0000 1.0000
53.9800 56.0000 1.0000
54.0400 60.0000 1.0000
54.1000 68.0000 1.0000
54.1600 74.0000 1.0000
54.2200 66.0000 1.0000
54.2800 94.0000 1.0000
54.3400 68.0000 1.0000
54.4000 79.0000 1.0000
54.4600 69.0000 1.0000
54.5200 63.0000 1.0000
54.5800 99.0000 1.0000
54.6400 127.0000 1.0000
54.7000 114.0000 1.0000
54.7600 96.0000 1.0000
54.8200 101.0000 1.0000
54.8800 110.0000 1.0000
54.9400 88.0000 1.0000
55.0000 99.0000 1.0000
55.0600 70.0000 1.0000
55.1200 75.0000 1.0000
55.1800 80.0000 1.0000
55.2400 62.0000 1.0000
55.3000 62.0000 1.0000
55.3600 68.0000 1.0000
55.4200 68.0000 1.0000
55.4800 72.0000 1.0000
55.5400 56.0000 1.0000
55.6000 56.0000 1.0000
55.6600 75.0000 1.0000
55.7200 59.0000 1.0000
55.7800 66.0000 1.0000
55.8400 76.0000 1.0000
55.9000 67.0000 1.0000
55.9600 63.0000 1.0000
56.0200 57.0000 1.0000
56.0800 68.0000 1.0000
56.1400 55.0000 1.0000
56.2000 74.0000 1.0000
56.2600 73.0000 1.0000
56.3200 58.0000 1.0000
56.3800 59.0000 1.0000
56.4400 54.0000 1.0000
56.5000 84.0000 1.0000
56.5600 74.0000 1.0000
56.6200 75.0000 1.0000
56.6800 106.0000 1.0000
56.7400 107.0000 1.0000
56.8000 155.0000 1.0000
56.8600 161.0000 1.0000
56.9200 161.0000 1.0000
56.9800 136.0000 1.0000
57.0400 113.0000 1.0000
57.1000 77.0000 1.0000
57.1600 84.0000 1.0000
57.2200 61.0000 1.0000
57.2800 68.0000 1.0000
57.3400 78.0000 1.0000
57.4000 58.0000 1.0000
57.4600 74.0000 1.0000
57.5200 72.0000 1.0000
57.5800 63.0000 1.0000
57.6400 62.0000 1.0000
57.7000 46.0000 1.0000
57.7600 66.0000 1.0000
57.8200 74.0000 1.0000
57.8800 67.0000 1.0000
57.9400 56.0000 1.0000
58.0000 68.0000 1.0000
58.0600 74.0000 1.0000
58.1200 65.0000 1.0000
58.1800 48.0000 1.0000
58.2400 63.0000 1.0000
58.3000 62.0000 1.0000
58.3600 78.0000 1.0000
58.4200 59.0000 1.0000
58.4800 73.0000 1.0000
58.5400 82.0000 1.0000
58.6000 62.0000 1.0000
58.6600 77.0000 1.0000
58.7200 92.0000 1.0000
58.7800 50.0000 1.0000
58.8400 77.0000 1.0000
58.9000 50.0000 1.0000
58.9600 74.0000 1.0000
59.0200 59.0000 1.0000
59.0800 74.0000 1.0000
59.1400 72.0000 1.0000
59.2000 68.0000 1.0000
59.2600 64.0000 1.0000
59.3200 78.0000 1.0000
59.3800 52.0000 1.0000
59.4400 67.0000 1.0000
59.5000 56.0000 1.0000
59.5600 50.0000 1.0000
59.6200 54.0000 1.0000
59.6800 50.0000 1.0000
59.7400 57.0000 1.0000
59.8000 60.0000 1.0000
59.8600 84.0000 1.0000
59.9200 57.0000 1.0000
59.9800 62.0000 1.0000
60.0400 73.0000 1.0000
60.1000 81.0000 1.0000
60.1600 66.0000 1.0000
60.2200 63.0000 1.0000
60.2800 73.0000 1.0000
60.3400 62.0000 1.0000
60.4000 72.0000 1.0000
60.4600 80.0000 1.0000
60.5200 95.0000 1.0000
60.5800 134.0000 1.0000
60.6400 97.0000 1.0000
60.7000 120.0000 1.0000
60.7600 123.0000 1.0000
60.8200 94.0000 1.0000
60.8800 78.0000 1.0000
60.9400 65.0000 1.0000
61.0000 82.0000 1.0000
61.0600 67.0000 1.0000
61.1200 74.0000 1.0000
61.1800 66.0000 1.0000
61.2400 78.0000 1.0000
61.3000 103.0000 1.0000
61.3600 109.0000 1.0000
61.4200 154.0000 1.0000
61.4800 195.0000 1.0000
61.5400 238.0000 1.0000
61.6000 192.0000 1.0000
61.6600 160.0000 1.0000
61.7200 115.0000 1.0000
61.7800 98.0000 1.0000
61.8400 73.0000 1.0000
61.9000 65.0000 1.0000
61.9600 60.0000 1.0000
62.0200 68.0000 1.0000
62.0800 53.0000 1.0000
62.1400 92.0000 1.0000
62.2000 106.0000 1.0000
62.2600 110.0000 1.0000
62.3200 100.0000 1.0000
62.3800 88.0000 1.0000
62.4400 105.0000 1.0000
62.5000 99.0000 1.0000
62.5600 76.0000 1.0000
62.6200 64.0000 1.0000
62.6800 59.0000 1.0000
62.7400 52.0000 1.0000
62.8000 59.0000 1.0000
62.8600 48.0000 1.0000
62.9200 66.0000 1.0000
62.9800 53.0000 1.0000
63.0400 45.0000 1.0000
63.1000 56.0000 1.0000
63.1600 58.0000 1.0000
63.2200 57.0000 1.0000
63.2800 53.0000 1.0000
63.3400 52.0000 1.0000
63.4000 40.0000 1.0000
63.4600 50.0000 1.0000
63.5200 66.0000 1.0000
63.5800 60.0000 1.0000
63.6400 47.0000 1.0000
63.7000 61.0000 1.0000
63.7600 48.0000 1.0000
63.8200 50.0000 1.0000
63.8800 51.0000 1.0000
63.9400 50.0000 1.0000
64.0000 51.0000 1.0000
64.0600 44.0000 1.0000
64.1200 50.0000 1.0000
64.1800 55.0000 1.0000
64.2400 49.0000 1.0000
64.3000 42.0000 1.0000
64.3600 53.0000 1.0000
64.4200 49.0000 1.0000
64.4800 59.0000 1.0000
64.5400 46.0000 1.0000
64.6000 55.0000 1.0000
64.6600 53.0000 1.0000
64.7200 51.0000 1.0000
64.7800 43.0000 1.0000
64.8400 69.0000 1.0000
64.9000 68.0000 1.0000
64.9600 59.0000 1.0000
65.0200 51.0000 1.0000
65.0800 53.0000 1.0000
65.1400 61.0000 1.0000
65.2000 73.0000 1.0000
65.2600 106.0000 1.0000
65.3200 88.0000 1.0000
65.3800 82.0000 1.0000
65.4400 111.0000 1.0000
65.5000 92.0000 1.0000
65.5600 94.0000 1.0000
65.6200 64.0000 1.0000
65.6800 66.0000 1.0000
65.7400 56.0000 1.0000
65.8000 53.0000 1.0000
65.8600 60.0000 1.0000
65.9200 36.0000 1.0000
65.9800 50.0000 1.0000
66.0400 50.0000 1.0000
66.1000 46.0000 1.0000
66.1600 53.0000 1.0000
66.2200 57.0000 1.0000
66.2800 49.0000 1.0000
66.3400 61.0000 1.0000
66.4000 59.0000 1.0000
66.4600 46.0000 1.0000
66.5200 47.0000 1.0000
66.5800 49.0000 1.0000
66.6400 59.0000 1.0000
66.7000 63.0000 1.0000
66.7600 48.0000 1.0000
66.8200 53.0000 1.0000
66.8800 60.0000 1.0000
66.9400 67.0000 1.0000
67.0000 57.0000 1.0000
67.0600 74.0000 1.0000
67.1200 58.0000 1.0000
67.1800 47.0000 1.0000
67.2400 53.0000 1.0000
67.3000 53.0000 1.0000
67.3600 61.0000 1.0000
67.4200 55.0000 1.0000
67.4800 49.0000 1.0000
67.5400 48.0000 1.0000
67.6000 49.0000 1.0000
67.6600 65.0000 1.0000
67.7200 72.0000 1.0000
67.7800 67.0000 1.0000
67.8400 70.0000 1.0000
67.9000 72.0000 1.0000
67.9600 62.0000 1.0000
68.0200 48.0000 1.0000
68.0800 57.0000 1.0000
68.1400 40.0000 1.0000
68.2000 48.0000 1.0000
68.2600 48.0000 1.0000
68.3200 43.0000 1.0000
68.3800 44.0000 1.0000
68.4400 47.0000 1.0000
68.5000 55.0000 1.0000
68.5600 44.0000 1.0000
68.6200 34.0000 1.0000
68.6800 47.0000 1.0000
68.7400 51.0000 1.0000
68.8000 34.0000 1.0000
68.8600 39.0000 1.0000
68.9200 41.0000 1.0000
68.9800 53.0000 1.0000
69.0400 50.0000 1.0000
69.1000 54.0000 1.0000
69.1600 52.0000 1.0000
69.2200 63.0000 1.0000
69.2800 73.0000 1.0000
69.3400 101.0000 1.0000
69.4000 171.0000 1.0000
69.4600 240.0000 1.0000
69.5200 217.0000 1.0000
69.5800 149.0000 1.0000
69.6400 156.0000 1.0000
69.7000 173.0000 1.0000
69.7600 99.0000 1.0000
69.8200 67.0000 1.0000
69.8800 58.0000 1.0000
69.9400 51.0000 1.0000
70.0000 43.0000 1.0000
*RAS_INT_END
*RAS_DATA_END