File: Examples/data/La1.75Sr0.25CuO4.ras
*RAS_DATA_START
*RAS_HEADER_START
*DISP_FMT_X "%.2f"
*DISP_FMT_Y "%.0f"
*DISP_FULLSCALE "3486.0000000000"
*DISP_LINE_COLOR "255.0000000000"
*DISP_LINE_STYLE "0.0000000000"
*DISP_LINE_WIDTH "0.2500000000"
*DISP_NOTE "測定データ-1"
*DISP_OFFSET_Y "0.0000000000"
*DISP_PEAKSEARCH_UNIT_Y "cps"
*DISP_RANGE_BOTTOM "0.0000000000"
*DISP_RANGE_LEFT "5.0000000000"
*DISP_RANGE_LOGCUTOFF "0.0100000000"
*DISP_RANGE_RIGHT "85.0000000000"
*DISP_RANGE_TOP "3486.0000000000"
*DISP_SCALE_MODE_Y "0.0000000000"
*DISP_TAB_NAME "2θ/θ"
*DISP_TITLE_Y "強度"
*DISP_UNIT_Y "cps"
*DISP_WINDOW_NAME "MSG_MACROENGINE"
*FILE_COMMENT " "
*FILE_MD5 ""
*FILE_MEMO " "
*FILE_OPERATOR "Administrator"
*FILE_SAMPLE " "
*FILE_TYPE "RAS_RAW"
*FILE_USERGROUP "システムマネージャ"
*FILE_VERSION "1.0000000000"
*HW_ATTACHMENT_ID "ATT1025"
*HW_ATTACHMENT_NAME "標準試料台|Standard Sample Holder"
*HW_COUNTER_ID-0 "CUT0021"
*HW_COUNTER_ID-1 "CUT0020"
*HW_COUNTER_ID-2 "CUT0020"
*HW_COUNTER_ID-3 "CMC0021"
*HW_COUNTER_NAME-0 "SC-70|SC-70"
*HW_COUNTER_NAME-1 "None|None"
*HW_COUNTER_NAME-2 "None|None"
*HW_COUNTER_NAME-3 "検出器モノクロメータ|Detector monochromator"
*HW_COUNTER_SELECT_NAME "SC-70|SC-70"
*HW_ECP_HV "641.5000000000"
*HW_ECP_HV_UNIT "V"
*HW_GONIOMETER_ID "GON0070"
*HW_GONIOMETER_NAME "MiniFlex 300/600|MiniFlex 300/600"
*HW_GONIOMETER_RADIUS-0 "79.0"
*HW_GONIOMETER_RADIUS-1 "91.5"
*HW_GONIOMETER_RADIUS-2 "150.0"
*HW_GONIOMETER_RADIUS-3 "0"
*HW_GONIOMETER_RADIUS-4 "103.4"
*HW_GONIOMETER_RADIUS-5 "150.0"
*HW_GONIOMETER_RADIUS-6 "46.6"
*HW_GONIOMETER_RADIUS-7 "160.0"
*HW_I_OPT_ID-0 "ISL0021"
*HW_I_OPT_ID-1 "ISO0021"
*HW_I_OPT_NAME-0 "発散スリット|Divergence slit"
*HW_I_OPT_NAME-1 "入射平行スリット|Incident parallel slit"
*HW_R_ATTENUATER_AUTOMODE "0"
*HW_R_OPT_ID-0 "RSS0021"
*HW_R_OPT_ID-1 "RSO0021"
*HW_R_OPT_ID-2 "RRS0021"
*HW_R_OPT_NAME-0 "散乱スリット|Scattering slit"
*HW_R_OPT_NAME-1 "受光平行スリット|Receiving soller slit"
*HW_R_OPT_NAME-2 "受光スリット|Receiving slit"
*HW_SAMPLE_HOLDER_ID "SMP0000"
*HW_SAMPLE_HOLDER_NAME "無し|None"
*HW_XG_CURRENT_MAX "15"
*HW_XG_CURRENT_MIN "2"
*HW_XG_CURRENT_RESOLUTION "1"
*HW_XG_CURRENT_UNIT "mA"
*HW_XG_FOCUS "1mm x 10mm"
*HW_XG_FOCUS_TYPE "Normal"
*HW_XG_ID ""
*HW_XG_NAME "300W/600W 封入管-A|300W/600W Sealed tube-A"
*HW_XG_TARGET_ATOMIC_NUMBER "29.0000000000"
*HW_XG_TARGET_NAME "Cu"
*HW_XG_TYPE "Hermetic"
*HW_XG_VOLTAGE_MAX "40"
*HW_XG_VOLTAGE_MIN "20"
*HW_XG_VOLTAGE_RESOLUTION "1"
*HW_XG_VOLTAGE_UNIT "kV"
*HW_XG_WATT_MAX "1"
*HW_XG_WATT_UNIT "kW"
*HW_XG_WAVE_LENGTH_ALPHA1 "1.540593"
*HW_XG_WAVE_LENGTH_ALPHA2 "1.544414"
*HW_XG_WAVE_LENGTH_BETA "1.392250"
*MEAS_COND_AXIS_NAME-0 "2θ/θ"
*MEAS_COND_AXIS_NAME-1 "Soller(inc.)"
*MEAS_COND_AXIS_NAME-2 "IHS"
*MEAS_COND_AXIS_NAME-3 "DS"
*MEAS_COND_AXIS_NAME-4 "SS"
*MEAS_COND_AXIS_NAME-5 "Soller(rec.)"
*MEAS_COND_AXIS_NAME-6 "RS"
*MEAS_COND_AXIS_NAME-7 "フィルター"
*MEAS_COND_AXIS_NAME-8 "モノクロメータ"
*MEAS_COND_AXIS_NAME-9 "HV"
*MEAS_COND_AXIS_NAME-10 "PHA"
*MEAS_COND_AXIS_NAME_INTERNAL-0 "TwoThetaTheta"
*MEAS_COND_AXIS_NAME_INTERNAL-1 "IncidentSollerSlit"
*MEAS_COND_AXIS_NAME_INTERNAL-2 "IncidentAxdSlit"
*MEAS_COND_AXIS_NAME_INTERNAL-3 "IncidentSlitBox"
*MEAS_COND_AXIS_NAME_INTERNAL-4 "ReceivingSlitBox1"
*MEAS_COND_AXIS_NAME_INTERNAL-5 "ReceivingSollerSlit"
*MEAS_COND_AXIS_NAME_INTERNAL-6 "ReceivingSlitBox2"
*MEAS_COND_AXIS_NAME_INTERNAL-7 "Filter"
*MEAS_COND_AXIS_NAME_INTERNAL-8 "CounterMonochromator"
*MEAS_COND_AXIS_NAME_INTERNAL-9 "HV"
*MEAS_COND_AXIS_NAME_INTERNAL-10 "PHA"
*MEAS_COND_AXIS_NAME_MAGICNO-0 "268632064.0000000000"
*MEAS_COND_AXIS_NAME_MAGICNO-1 "20971521.0000000000"
*MEAS_COND_AXIS_NAME_MAGICNO-2 "22020097.0000000000"
*MEAS_COND_AXIS_NAME_MAGICNO-3 "22020097.0000000000"
*MEAS_COND_AXIS_NAME_MAGICNO-4 "23068673.0000000000"
*MEAS_COND_AXIS_NAME_MAGICNO-5 "20971521.0000000000"
*MEAS_COND_AXIS_NAME_MAGICNO-6 "23068673.0000000000"
*MEAS_COND_AXIS_NAME_MAGICNO-7 "20971521.0000000000"
*MEAS_COND_AXIS_NAME_MAGICNO-8 "20971521.0000000000"
*MEAS_COND_AXIS_NAME_MAGICNO-9 "0.0000000000"
*MEAS_COND_AXIS_NAME_MAGICNO-10 "0.0000000000"
*MEAS_COND_AXIS_OFFSET-0 "0.0000000000"
*MEAS_COND_AXIS_OFFSET-1 "-"
*MEAS_COND_AXIS_OFFSET-2 "-"
*MEAS_COND_AXIS_OFFSET-3 "-"
*MEAS_COND_AXIS_OFFSET-4 "-"
*MEAS_COND_AXIS_OFFSET-5 "-"
*MEAS_COND_AXIS_OFFSET-6 "-"
*MEAS_COND_AXIS_OFFSET-7 "-"
*MEAS_COND_AXIS_OFFSET-8 "-"
*MEAS_COND_AXIS_OFFSET-9 "-"
*MEAS_COND_AXIS_OFFSET-10 "-"
*MEAS_COND_AXIS_POSITION-0 "10.0000000000"
*MEAS_COND_AXIS_POSITION-1 "5.0deg"
*MEAS_COND_AXIS_POSITION-2 "10.0mm"
*MEAS_COND_AXIS_POSITION-3 "1.250deg"
*MEAS_COND_AXIS_POSITION-4 "1.250deg"
*MEAS_COND_AXIS_POSITION-5 "5.0deg"
*MEAS_COND_AXIS_POSITION-6 "0.3mm"
*MEAS_COND_AXIS_POSITION-7 "None"
*MEAS_COND_AXIS_POSITION-8 "Bent"
*MEAS_COND_AXIS_POSITION-9 "641.5000000000"
*MEAS_COND_AXIS_POSITION-10 "566.2500000000"
*MEAS_COND_AXIS_UNIT-0 "deg"
*MEAS_COND_AXIS_UNIT-1 ""
*MEAS_COND_AXIS_UNIT-2 ""
*MEAS_COND_AXIS_UNIT-3 ""
*MEAS_COND_AXIS_UNIT-4 ""
*MEAS_COND_AXIS_UNIT-5 ""
*MEAS_COND_AXIS_UNIT-6 ""
*MEAS_COND_AXIS_UNIT-7 ""
*MEAS_COND_AXIS_UNIT-8 ""
*MEAS_COND_AXIS_UNIT-9 "V"
*MEAS_COND_AXIS_UNIT-10 "mV"
*MEAS_COND_COUNTER_CNTLOSS_CORR "0.0000000000"
*MEAS_COND_COUNTER_PHABASE "566.2500000000"
*MEAS_COND_COUNTER_PHAWINDOW "878.7500000000"
*MEAS_COND_COUNTER_PHA_UNIT "mV"
*MEAS_COND_COUNTER_TAUDIFF "0.2500000000"
*MEAS_COND_COUNTER_TAUINT "0.7500000000"
*MEAS_COND_IRRADIATION_MODE "OFF"
*MEAS_COND_IRRADIATION_WIDTH ""
*MEAS_COND_OPT_ATTR " "
*MEAS_COND_OPT_NAME ""
*MEAS_COND_UNSYMMETRIC_MODE "OFF"
*MEAS_COND_XG_CURRENT "15.0000000000"
*MEAS_COND_XG_VOLTAGE "40.0000000000"
*MEAS_COND_XG_WAVE_TYPE "Ka"
*MEAS_DATA_COUNT "4001.0000000000"
*MEAS_SCAN_AXIS_X "2θ/θ"
*MEAS_SCAN_AXIS_X_INTERNAL "TwoThetaTheta"
*MEAS_SCAN_END_TIME "04/08/21 14:08:20"
*MEAS_SCAN_MODE "CONTINUOUS"
*MEAS_SCAN_MONITOR "0"
*MEAS_SCAN_RESOLUTION_X "0.0025"
*MEAS_SCAN_SPEED "2.0000"
*MEAS_SCAN_SPEED_UNIT "deg/min"
*MEAS_SCAN_START "5.0000000000"
*MEAS_SCAN_START_TIME "04/08/21 13:28:11"
*MEAS_SCAN_STEP "0.0200000000"
*MEAS_SCAN_STOP "85.0000000000"
*MEAS_SCAN_UNIT_X "deg"
*MEAS_SCAN_UNIT_Y "counts"
*SLIT_SYSTEM "0"
*RAS_HEADER_END
*RAS_INT_START
5.0000 31.0000 1.0000
5.0600 23.0000 1.0000
5.1200 29.0000 1.0000
5.1800 20.0000 1.0000
5.2400 31.0000 1.0000
5.3000 19.0000 1.0000
5.3600 20.0000 1.0000
5.4200 28.0000 1.0000
5.4800 14.0000 1.0000
5.5400 18.0000 1.0000
5.6000 31.0000 1.0000
5.6600 19.0000 1.0000
5.7200 29.0000 1.0000
5.7800 15.0000 1.0000
5.8400 17.0000 1.0000
5.9000 25.0000 1.0000
5.9600 24.0000 1.0000
6.0200 27.0000 1.0000
6.0800 26.0000 1.0000
6.1400 21.0000 1.0000
6.2000 32.0000 1.0000
6.2600 23.0000 1.0000
6.3200 27.0000 1.0000
6.3800 8.0000 1.0000
6.4400 22.0000 1.0000
6.5000 31.0000 1.0000
6.5600 32.0000 1.0000
6.6200 35.0000 1.0000
6.6800 18.0000 1.0000
6.7400 24.0000 1.0000
6.8000 17.0000 1.0000
6.8600 28.0000 1.0000
6.9200 33.0000 1.0000
6.9800 24.0000 1.0000
7.0400 25.0000 1.0000
7.1000 19.0000 1.0000
7.1600 31.0000 1.0000
7.2200 31.0000 1.0000
7.2800 43.0000 1.0000
7.3400 32.0000 1.0000
7.4000 22.0000 1.0000
7.4600 27.0000 1.0000
7.5200 36.0000 1.0000
7.5800 29.0000 1.0000
7.6400 25.0000 1.0000
7.7000 29.0000 1.0000
7.7600 22.0000 1.0000
7.8200 25.0000 1.0000
7.8800 34.0000 1.0000
7.9400 19.0000 1.0000
8.0000 36.0000 1.0000
8.0600 21.0000 1.0000
8.1200 28.0000 1.0000
8.1800 28.0000 1.0000
8.2400 31.0000 1.0000
8.3000 27.0000 1.0000
8.3600 28.0000 1.0000
8.4200 17.0000 1.0000
8.4800 28.0000 1.0000
8.5400 23.0000 1.0000
8.6000 34.0000 1.0000
8.6600 41.0000 1.0000
8.7200 23.0000 1.0000
8.7800 26.0000 1.0000
8.8400 23.0000 1.0000
8.9000 23.0000 1.0000
8.9600 21.0000 1.0000
9.0200 31.0000 1.0000
9.0800 33.0000 1.0000
9.1400 26.0000 1.0000
9.2000 34.0000 1.0000
9.2600 23.0000 1.0000
9.3200 19.0000 1.0000
9.3800 26.0000 1.0000
9.4400 35.0000 1.0000
9.5000 27.0000 1.0000
9.5600 30.0000 1.0000
9.6200 23.0000 1.0000
9.6800 30.0000 1.0000
9.7400 16.0000 1.0000
9.8000 27.0000 1.0000
9.8600 32.0000 1.0000
9.9200 29.0000 1.0000
9.9800 30.0000 1.0000
10.0400 27.0000 1.0000
10.1000 34.0000 1.0000
10.1600 40.0000 1.0000
10.2200 33.0000 1.0000
10.2800 29.0000 1.0000
10.3400 24.0000 1.0000
10.4000 34.0000 1.0000
10.4600 26.0000 1.0000
10.5200 30.0000 1.0000
10.5800 21.0000 1.0000
10.6400 19.0000 1.0000
10.7000 35.0000 1.0000
10.7600 29.0000 1.0000
10.8200 38.0000 1.0000
10.8800 33.0000 1.0000
10.9400 30.0000 1.0000
11.0000 26.0000 1.0000
11.0600 35.0000 1.0000
11.1200 36.0000 1.0000
11.1800 38.0000 1.0000
11.2400 28.0000 1.0000
11.3000 32.0000 1.0000
11.3600 28.0000 1.0000
11.4200 42.0000 1.0000
11.4800 31.0000 1.0000
11.5400 40.0000 1.0000
11.6000 35.0000 1.0000
11.6600 35.0000 1.0000
11.7200 27.0000 1.0000
11.7800 23.0000 1.0000
11.8400 37.0000 1.0000
11.9000 37.0000 1.0000
11.9600 39.0000 1.0000
12.0200 26.0000 1.0000
12.0800 29.0000 1.0000
12.1400 41.0000 1.0000
12.2000 25.0000 1.0000
12.2600 30.0000 1.0000
12.3200 29.0000 1.0000
12.3800 31.0000 1.0000
12.4400 26.0000 1.0000
12.5000 37.0000 1.0000
12.5600 33.0000 1.0000
12.6200 34.0000 1.0000
12.6800 32.0000 1.0000
12.7400 30.0000 1.0000
12.8000 51.0000 1.0000
12.8600 38.0000 1.0000
12.9200 27.0000 1.0000
12.9800 38.0000 1.0000
13.0400 40.0000 1.0000
13.1000 26.0000 1.0000
13.1600 35.0000 1.0000
13.2200 44.0000 1.0000
13.2800 38.0000 1.0000
13.3400 50.0000 1.0000
13.4000 66.0000 1.0000
13.4600 75.0000 1.0000
13.5200 65.0000 1.0000
13.5800 44.0000 1.0000
13.6400 51.0000 1.0000
13.7000 44.0000 1.0000
13.7600 47.0000 1.0000
13.8200 36.0000 1.0000
13.8800 41.0000 1.0000
13.9400 19.0000 1.0000
14.0000 29.0000 1.0000
14.0600 54.0000 1.0000
14.1200 35.0000 1.0000
14.1800 40.0000 1.0000
14.2400 41.0000 1.0000
14.3000 40.0000 1.0000
14.3600 34.0000 1.0000
14.4200 35.0000 1.0000
14.4800 39.0000 1.0000
14.5400 37.0000 1.0000
14.6000 37.0000 1.0000
14.6600 40.0000 1.0000
14.7200 32.0000 1.0000
14.7800 45.0000 1.0000
14.8400 34.0000 1.0000
14.9000 37.0000 1.0000
14.9600 33.0000 1.0000
15.0200 30.0000 1.0000
15.0800 45.0000 1.0000
15.1400 49.0000 1.0000
15.2000 32.0000 1.0000
15.2600 42.0000 1.0000
15.3200 42.0000 1.0000
15.3800 32.0000 1.0000
15.4400 37.0000 1.0000
15.5000 41.0000 1.0000
15.5600 42.0000 1.0000
15.6200 47.0000 1.0000
15.6800 45.0000 1.0000
15.7400 27.0000 1.0000
15.8000 39.0000 1.0000
15.8600 32.0000 1.0000
15.9200 40.0000 1.0000
15.9800 53.0000 1.0000
16.0400 41.0000 1.0000
16.1000 44.0000 1.0000
16.1600 52.0000 1.0000
16.2200 32.0000 1.0000
16.2800 41.0000 1.0000
16.3400 41.0000 1.0000
16.4000 36.0000 1.0000
16.4600 35.0000 1.0000
16.5200 34.0000 1.0000
16.5800 50.0000 1.0000
16.6400 44.0000 1.0000
16.7000 45.0000 1.0000
16.7600 42.0000 1.0000
16.8200 37.0000 1.0000
16.8800 41.0000 1.0000
16.9400 43.0000 1.0000
17.0000 42.0000 1.0000
17.0600 42.0000 1.0000
17.1200 45.0000 1.0000
17.1800 38.0000 1.0000
17.2400 37.0000 1.0000
17.3000 56.0000 1.0000
17.3600 50.0000 1.0000
17.4200 45.0000 1.0000
17.4800 54.0000 1.0000
17.5400 46.0000 1.0000
17.6000 38.0000 1.0000
17.6600 37.0000 1.0000
17.7200 45.0000 1.0000
17.7800 43.0000 1.0000
17.8400 44.0000 1.0000
17.9000 46.0000 1.0000
17.9600 42.0000 1.0000
18.0200 50.0000 1.0000
18.0800 34.0000 1.0000
18.1400 52.0000 1.0000
18.2000 55.0000 1.0000
18.2600 51.0000 1.0000
18.3200 40.0000 1.0000
18.3800 47.0000 1.0000
18.4400 44.0000 1.0000
18.5000 34.0000 1.0000
18.5600 42.0000 1.0000
18.6200 47.0000 1.0000
18.6800 55.0000 1.0000
18.7400 47.0000 1.0000
18.8000 39.0000 1.0000
18.8600 41.0000 1.0000
18.9200 53.0000 1.0000
18.9800 54.0000 1.0000
19.0400 50.0000 1.0000
19.1000 45.0000 1.0000
19.1600 53.0000 1.0000
19.2200 43.0000 1.0000
19.2800 43.0000 1.0000
19.3400 46.0000 1.0000
19.4000 48.0000 1.0000
19.4600 54.0000 1.0000
19.5200 44.0000 1.0000
19.5800 47.0000 1.0000
19.6400 44.0000 1.0000
19.7000 54.0000 1.0000
19.7600 38.0000 1.0000
19.8200 47.0000 1.0000
19.8800 56.0000 1.0000
19.9400 61.0000 1.0000
20.0000 49.0000 1.0000
20.0600 60.0000 1.0000
20.1200 39.0000 1.0000
20.1800 42.0000 1.0000
20.2400 43.0000 1.0000
20.3000 61.0000 1.0000
20.3600 48.0000 1.0000
20.4200 42.0000 1.0000
20.4800 51.0000 1.0000
20.5400 40.0000 1.0000
20.6000 45.0000 1.0000
20.6600 60.0000 1.0000
20.7200 53.0000 1.0000
20.7800 60.0000 1.0000
20.8400 44.0000 1.0000
20.9000 46.0000 1.0000
20.9600 41.0000 1.0000
21.0200 44.0000 1.0000
21.0800 45.0000 1.0000
21.1400 32.0000 1.0000
21.2000 65.0000 1.0000
21.2600 39.0000 1.0000
21.3200 39.0000 1.0000
21.3800 50.0000 1.0000
21.4400 47.0000 1.0000
21.5000 55.0000 1.0000
21.5600 51.0000 1.0000
21.6200 62.0000 1.0000
21.6800 44.0000 1.0000
21.7400 43.0000 1.0000
21.8000 51.0000 1.0000
21.8600 52.0000 1.0000
21.9200 55.0000 1.0000
21.9800 52.0000 1.0000
22.0400 60.0000 1.0000
22.1000 62.0000 1.0000
22.1600 61.0000 1.0000
22.2200 41.0000 1.0000
22.2800 60.0000 1.0000
22.3400 52.0000 1.0000
22.4000 39.0000 1.0000
22.4600 43.0000 1.0000
22.5200 55.0000 1.0000
22.5800 56.0000 1.0000
22.6400 63.0000 1.0000
22.7000 46.0000 1.0000
22.7600 45.0000 1.0000
22.8200 60.0000 1.0000
22.8800 44.0000 1.0000
22.9400 42.0000 1.0000
23.0000 56.0000 1.0000
23.0600 51.0000 1.0000
23.1200 42.0000 1.0000
23.1800 55.0000 1.0000
23.2400 50.0000 1.0000
23.3000 45.0000 1.0000
23.3600 52.0000 1.0000
23.4200 52.0000 1.0000
23.4800 42.0000 1.0000
23.5400 58.0000 1.0000
23.6000 42.0000 1.0000
23.6600 47.0000 1.0000
23.7200 51.0000 1.0000
23.7800 46.0000 1.0000
23.8400 48.0000 1.0000
23.9000 56.0000 1.0000
23.9600 55.0000 1.0000
24.0200 53.0000 1.0000
24.0800 51.0000 1.0000
24.1400 60.0000 1.0000
24.2000 46.0000 1.0000
24.2600 77.0000 1.0000
24.3200 70.0000 1.0000
24.3800 98.0000 1.0000
24.4400 148.0000 1.0000
24.5000 257.0000 1.0000
24.5600 341.0000 1.0000
24.6200 418.0000 1.0000
24.6800 324.0000 1.0000
24.7400 237.0000 1.0000
24.8000 112.0000 1.0000
24.8600 73.0000 1.0000
24.9200 57.0000 1.0000
24.9800 69.0000 1.0000
25.0400 53.0000 1.0000
25.1000 54.0000 1.0000
25.1600 52.0000 1.0000
25.2200 61.0000 1.0000
25.2800 54.0000 1.0000
25.3400 52.0000 1.0000
25.4000 34.0000 1.0000
25.4600 63.0000 1.0000
25.5200 49.0000 1.0000
25.5800 53.0000 1.0000
25.6400 54.0000 1.0000
25.7000 57.0000 1.0000
25.7600 44.0000 1.0000
25.8200 53.0000 1.0000
25.8800 54.0000 1.0000
25.9400 58.0000 1.0000
26.0000 59.0000 1.0000
26.0600 85.0000 1.0000
26.1200 82.0000 1.0000
26.1800 96.0000 1.0000
26.2400 97.0000 1.0000
26.3000 61.0000 1.0000
26.3600 55.0000 1.0000
26.4200 49.0000 1.0000
26.4800 60.0000 1.0000
26.5400 58.0000 1.0000
26.6000 55.0000 1.0000
26.6600 57.0000 1.0000
26.7200 67.0000 1.0000
26.7800 66.0000 1.0000
26.8400 100.0000 1.0000
26.9000 128.0000 1.0000
26.9600 199.0000 1.0000
27.0200 260.0000 1.0000
27.0800 220.0000 1.0000
27.1400 162.0000 1.0000
27.2000 102.0000 1.0000
27.2600 91.0000 1.0000
27.3200 72.0000 1.0000
27.3800 82.0000 1.0000
27.4400 68.0000 1.0000
27.5000 66.0000 1.0000
27.5600 63.0000 1.0000
27.6200 89.0000 1.0000
27.6800 79.0000 1.0000
27.7400 55.0000 1.0000
27.8000 63.0000 1.0000
27.8600 55.0000 1.0000
27.9200 51.0000 1.0000
27.9800 45.0000 1.0000
28.0400 48.0000 1.0000
28.1000 54.0000 1.0000
28.1600 58.0000 1.0000
28.2200 52.0000 1.0000
28.2800 38.0000 1.0000
28.3400 40.0000 1.0000
28.4000 62.0000 1.0000
28.4600 57.0000 1.0000
28.5200 50.0000 1.0000
28.5800 49.0000 1.0000
28.6400 58.0000 1.0000
28.7000 59.0000 1.0000
28.7600 43.0000 1.0000
28.8200 55.0000 1.0000
28.8800 66.0000 1.0000
28.9400 51.0000 1.0000
29.0000 66.0000 1.0000
29.0600 67.0000 1.0000
29.1200 85.0000 1.0000
29.1800 105.0000 1.0000
29.2400 102.0000 1.0000
29.3000 89.0000 1.0000
29.3600 59.0000 1.0000
29.4200 59.0000 1.0000
29.4800 53.0000 1.0000
29.5400 53.0000 1.0000
29.6000 51.0000 1.0000
29.6600 45.0000 1.0000
29.7200 51.0000 1.0000
29.7800 47.0000 1.0000
29.8400 80.0000 1.0000
29.9000 124.0000 1.0000
29.9600 178.0000 1.0000
30.0200 254.0000 1.0000
30.0800 196.0000 1.0000
30.1400 144.0000 1.0000
30.2000 87.0000 1.0000
30.2600 62.0000 1.0000
30.3200 74.0000 1.0000
30.3800 47.0000 1.0000
30.4400 77.0000 1.0000
30.5000 53.0000 1.0000
30.5600 63.0000 1.0000
30.6200 50.0000 1.0000
30.6800 61.0000 1.0000
30.7400 81.0000 1.0000
30.8000 90.0000 1.0000
30.8600 90.0000 1.0000
30.9200 104.0000 1.0000
30.9800 123.0000 1.0000
31.0400 230.0000 1.0000
31.1000 459.0000 1.0000
31.1600 885.0000 1.0000
31.2200 1536.0000 1.0000
31.2800 1716.0000 1.0000
31.3400 1318.0000 1.0000
31.4000 888.0000 1.0000
31.4600 619.0000 1.0000
31.5200 508.0000 1.0000
31.5800 455.0000 1.0000
31.6400 374.0000 1.0000
31.7000 259.0000 1.0000
31.7600 158.0000 1.0000
31.8200 108.0000 1.0000
31.8800 93.0000 1.0000
31.9400 76.0000 1.0000
32.0000 63.0000 1.0000
32.0600 47.0000 1.0000
32.1200 47.0000 1.0000
32.1800 48.0000 1.0000
32.2400 58.0000 1.0000
32.3000 59.0000 1.0000
32.3600 45.0000 1.0000
32.4200 44.0000 1.0000
32.4800 51.0000 1.0000
32.5400 49.0000 1.0000
32.6000 51.0000 1.0000
32.6600 49.0000 1.0000
32.7200 45.0000 1.0000
32.7800 51.0000 1.0000
32.8400 49.0000 1.0000
32.9000 50.0000 1.0000
32.9600 58.0000 1.0000
33.0200 54.0000 1.0000
33.0800 47.0000 1.0000
33.1400 64.0000 1.0000
33.2000 76.0000 1.0000
33.2600 93.0000 1.0000
33.3200 128.0000 1.0000
33.3800 148.0000 1.0000
33.4400 275.0000 1.0000
33.5000 490.0000 1.0000
33.5600 785.0000 1.0000
33.6200 972.0000 1.0000
33.6800 1071.0000 1.0000
33.7400 1002.0000 1.0000
33.8000 778.0000 1.0000
33.8600 412.0000 1.0000
33.9200 203.0000 1.0000
33.9800 124.0000 1.0000
34.0400 80.0000 1.0000
34.1000 69.0000 1.0000
34.1600 57.0000 1.0000
34.2200 54.0000 1.0000
34.2800 57.0000 1.0000
34.3400 45.0000 1.0000
34.4000 53.0000 1.0000
34.4600 62.0000 1.0000
34.5200 40.0000 1.0000
34.5800 53.0000 1.0000
34.6400 47.0000 1.0000
34.7000 46.0000 1.0000
34.7600 42.0000 1.0000
34.8200 51.0000 1.0000
34.8800 56.0000 1.0000
34.9400 39.0000 1.0000
35.0000 44.0000 1.0000
35.0600 41.0000 1.0000
35.1200 52.0000 1.0000
35.1800 39.0000 1.0000
35.2400 42.0000 1.0000
35.3000 48.0000 1.0000
35.3600 37.0000 1.0000
35.4200 40.0000 1.0000
35.4800 30.0000 1.0000
35.5400 48.0000 1.0000
35.6000 51.0000 1.0000
35.6600 44.0000 1.0000
35.7200 41.0000 1.0000
35.7800 53.0000 1.0000
35.8400 38.0000 1.0000
35.9000 40.0000 1.0000
35.9600 53.0000 1.0000
36.0200 40.0000 1.0000
36.0800 53.0000 1.0000
36.1400 42.0000 1.0000
36.2000 56.0000 1.0000
36.2600 49.0000 1.0000
36.3200 65.0000 1.0000
36.3800 64.0000 1.0000
36.4400 55.0000 1.0000
36.5000 59.0000 1.0000
36.5600 61.0000 1.0000
36.6200 58.0000 1.0000
36.6800 35.0000 1.0000
36.7400 48.0000 1.0000
36.8000 40.0000 1.0000
36.8600 33.0000 1.0000
36.9200 33.0000 1.0000
36.9800 41.0000 1.0000
37.0400 54.0000 1.0000
37.1000 46.0000 1.0000
37.1600 45.0000 1.0000
37.2200 45.0000 1.0000
37.2800 43.0000 1.0000
37.3400 48.0000 1.0000
37.4000 46.0000 1.0000
37.4600 37.0000 1.0000
37.5200 38.0000 1.0000
37.5800 38.0000 1.0000
37.6400 40.0000 1.0000
37.7000 47.0000 1.0000
37.7600 34.0000 1.0000
37.8200 33.0000 1.0000
37.8800 50.0000 1.0000
37.9400 44.0000 1.0000
38.0000 37.0000 1.0000
38.0600 40.0000 1.0000
38.1200 37.0000 1.0000
38.1800 38.0000 1.0000
38.2400 35.0000 1.0000
38.3000 41.0000 1.0000
38.3600 36.0000 1.0000
38.4200 58.0000 1.0000
38.4800 47.0000 1.0000
38.5400 39.0000 1.0000
38.6000 44.0000 1.0000
38.6600 43.0000 1.0000
38.7200 40.0000 1.0000
38.7800 52.0000 1.0000
38.8400 39.0000 1.0000
38.9000 51.0000 1.0000
38.9600 23.0000 1.0000
39.0200 38.0000 1.0000
39.0800 43.0000 1.0000
39.1400 40.0000 1.0000
39.2000 34.0000 1.0000
39.2600 41.0000 1.0000
39.3200 52.0000 1.0000
39.3800 57.0000 1.0000
39.4400 51.0000 1.0000
39.5000 82.0000 1.0000
39.5600 80.0000 1.0000
39.6200 71.0000 1.0000
39.6800 70.0000 1.0000
39.7400 54.0000 1.0000
39.8000 50.0000 1.0000
39.8600 44.0000 1.0000
39.9200 47.0000 1.0000
39.9800 38.0000 1.0000
40.0400 37.0000 1.0000
40.1000 48.0000 1.0000
40.1600 48.0000 1.0000
40.2200 43.0000 1.0000
40.2800 41.0000 1.0000
40.3400 42.0000 1.0000
40.4000 45.0000 1.0000
40.4600 37.0000 1.0000
40.5200 53.0000 1.0000
40.5800 51.0000 1.0000
40.6400 56.0000 1.0000
40.7000 54.0000 1.0000
40.7600 69.0000 1.0000
40.8200 92.0000 1.0000
40.8800 138.0000 1.0000
40.9400 166.0000 1.0000
41.0000 197.0000 1.0000
41.0600 184.0000 1.0000
41.1200 130.0000 1.0000
41.1800 116.0000 1.0000
41.2400 86.0000 1.0000
41.3000 80.0000 1.0000
41.3600 68.0000 1.0000
41.4200 78.0000 1.0000
41.4800 89.0000 1.0000
41.5400 90.0000 1.0000
41.6000 144.0000 1.0000
41.6600 260.0000 1.0000
41.7200 382.0000 1.0000
41.7800 343.0000 1.0000
41.8400 283.0000 1.0000
41.9000 182.0000 1.0000
41.9600 125.0000 1.0000
42.0200 103.0000 1.0000
42.0800 99.0000 1.0000
42.1400 75.0000 1.0000
42.2000 74.0000 1.0000
42.2600 77.0000 1.0000
42.3200 75.0000 1.0000
42.3800 74.0000 1.0000
42.4400 77.0000 1.0000
42.5000 71.0000 1.0000
42.5600 58.0000 1.0000
42.6200 51.0000 1.0000
42.6800 54.0000 1.0000
42.7400 36.0000 1.0000
42.8000 43.0000 1.0000
42.8600 48.0000 1.0000
42.9200 34.0000 1.0000
42.9800 39.0000 1.0000
43.0400 52.0000 1.0000
43.1000 48.0000 1.0000
43.1600 50.0000 1.0000
43.2200 61.0000 1.0000
43.2800 46.0000 1.0000
43.3400 73.0000 1.0000
43.4000 84.0000 1.0000
43.4600 125.0000 1.0000
43.5200 256.0000 1.0000
43.5800 351.0000 1.0000
43.6400 412.0000 1.0000
43.7000 445.0000 1.0000
43.7600 330.0000 1.0000
43.8200 249.0000 1.0000
43.8800 182.0000 1.0000
43.9400 153.0000 1.0000
44.0000 119.0000 1.0000
44.0600 106.0000 1.0000
44.1200 125.0000 1.0000
44.1800 74.0000 1.0000
44.2400 82.0000 1.0000
44.3000 61.0000 1.0000
44.3600 65.0000 1.0000
44.4200 49.0000 1.0000
44.4800 43.0000 1.0000
44.5400 41.0000 1.0000
44.6000 36.0000 1.0000
44.6600 41.0000 1.0000
44.7200 52.0000 1.0000
44.7800 45.0000 1.0000
44.8400 57.0000 1.0000
44.9000 39.0000 1.0000
44.9600 40.0000 1.0000
45.0200 39.0000 1.0000
45.0800 31.0000 1.0000
45.1400 52.0000 1.0000
45.2000 32.0000 1.0000
45.2600 49.0000 1.0000
45.3200 38.0000 1.0000
45.3800 48.0000 1.0000
45.4400 30.0000 1.0000
45.5000 31.0000 1.0000
45.5600 48.0000 1.0000
45.6200 43.0000 1.0000
45.6800 53.0000 1.0000
45.7400 42.0000 1.0000
45.8000 43.0000 1.0000
45.8600 45.0000 1.0000
45.9200 41.0000 1.0000
45.9800 62.0000 1.0000
46.0400 63.0000 1.0000
46.1000 89.0000 1.0000
46.1600 103.0000 1.0000
46.2200 106.0000 1.0000
46.2800 74.0000 1.0000
46.3400 63.0000 1.0000
46.4000 67.0000 1.0000
46.4600 46.0000 1.0000
46.5200 56.0000 1.0000
46.5800 53.0000 1.0000
46.6400 34.0000 1.0000
46.7000 50.0000 1.0000
46.7600 40.0000 1.0000
46.8200 45.0000 1.0000
46.8800 43.0000 1.0000
46.9400 46.0000 1.0000
47.0000 39.0000 1.0000
47.0600 50.0000 1.0000
47.1200 46.0000 1.0000
47.1800 35.0000 1.0000
47.2400 35.0000 1.0000
47.3000 35.0000 1.0000
47.3600 52.0000 1.0000
47.4200 39.0000 1.0000
47.4800 42.0000 1.0000
47.5400 61.0000 1.0000
47.6000 57.0000 1.0000
47.6600 42.0000 1.0000
47.7200 45.0000 1.0000
47.7800 48.0000 1.0000
47.8400 54.0000 1.0000
47.9000 60.0000 1.0000
47.9600 98.0000 1.0000
48.0200 120.0000 1.0000
48.0800 214.0000 1.0000
48.1400 240.0000 1.0000
48.2000 318.0000 1.0000
48.2600 392.0000 1.0000
48.3200 382.0000 1.0000
48.3800 397.0000 1.0000
48.4400 431.0000 1.0000
48.5000 315.0000 1.0000
48.5600 218.0000 1.0000
48.6200 130.0000 1.0000
48.6800 77.0000 1.0000
48.7400 63.0000 1.0000
48.8000 53.0000 1.0000
48.8600 47.0000 1.0000
48.9200 58.0000 1.0000
48.9800 53.0000 1.0000
49.0400 51.0000 1.0000
49.1000 39.0000 1.0000
49.1600 44.0000 1.0000
49.2200 52.0000 1.0000
49.2800 45.0000 1.0000
49.3400 44.0000 1.0000
49.4000 55.0000 1.0000
49.4600 48.0000 1.0000
49.5200 37.0000 1.0000
49.5800 43.0000 1.0000
49.6400 32.0000 1.0000
49.7000 37.0000 1.0000
49.7600 51.0000 1.0000
49.8200 41.0000 1.0000
49.8800 41.0000 1.0000
49.9400 56.0000 1.0000
50.0000 38.0000 1.0000
50.0600 51.0000 1.0000
50.1200 54.0000 1.0000
50.1800 49.0000 1.0000
50.2400 43.0000 1.0000
50.3000 57.0000 1.0000
50.3600 37.0000 1.0000
50.4200 52.0000 1.0000
50.4800 49.0000 1.0000
50.5400 48.0000 1.0000
50.6000 36.0000 1.0000
50.6600 38.0000 1.0000
50.7200 39.0000 1.0000
50.7800 34.0000 1.0000
50.8400 45.0000 1.0000
50.9000 38.0000 1.0000
50.9600 40.0000 1.0000
51.0200 49.0000 1.0000
51.0800 43.0000 1.0000
51.1400 43.0000 1.0000
51.2000 44.0000 1.0000
51.2600 44.0000 1.0000
51.3200 41.0000 1.0000
51.3800 47.0000 1.0000
51.4400 41.0000 1.0000
51.5000 32.0000 1.0000
51.5600 51.0000 1.0000
51.6200 40.0000 1.0000
51.6800 52.0000 1.0000
51.7400 41.0000 1.0000
51.8000 44.0000 1.0000
51.8600 46.0000 1.0000
51.9200 53.0000 1.0000
51.9800 58.0000 1.0000
52.0400 54.0000 1.0000
52.1000 76.0000 1.0000
52.1600 94.0000 1.0000
52.2200 95.0000 1.0000
52.2800 57.0000 1.0000
52.3400 61.0000 1.0000
52.4000 53.0000 1.0000
52.4600 57.0000 1.0000
52.5200 44.0000 1.0000
52.5800 42.0000 1.0000
52.6400 35.0000 1.0000
52.7000 33.0000 1.0000
52.7600 44.0000 1.0000
52.8200 41.0000 1.0000
52.8800 52.0000 1.0000
52.9400 48.0000 1.0000
53.0000 52.0000 1.0000
53.0600 33.0000 1.0000
53.1200 49.0000 1.0000
53.1800 38.0000 1.0000
53.2400 43.0000 1.0000
53.3000 64.0000 1.0000
53.3600 49.0000 1.0000
53.4200 47.0000 1.0000
53.4800 36.0000 1.0000
53.5400 53.0000 1.0000
53.6000 54.0000 1.0000
53.6600 60.0000 1.0000
53.7200 64.0000 1.0000
53.7800 94.0000 1.0000
53.8400 140.0000 1.0000
53.9000 184.0000 1.0000
53.9600 206.0000 1.0000
54.0200 182.0000 1.0000
54.0800 165.0000 1.0000
54.1400 188.0000 1.0000
54.2000 185.0000 1.0000
54.2600 240.0000 1.0000
54.3200 232.0000 1.0000
54.3800 202.0000 1.0000
54.4400 183.0000 1.0000
54.5000 145.0000 1.0000
54.5600 129.0000 1.0000
54.6200 125.0000 1.0000
54.6800 144.0000 1.0000
54.7400 115.0000 1.0000
54.8000 145.0000 1.0000
54.8600 115.0000 1.0000
54.9200 119.0000 1.0000
54.9800 111.0000 1.0000
55.0400 122.0000 1.0000
55.1000 89.0000 1.0000
55.1600 91.0000 1.0000
55.2200 81.0000 1.0000
55.2800 85.0000 1.0000
55.3400 85.0000 1.0000
55.4000 99.0000 1.0000
55.4600 138.0000 1.0000
55.5200 145.0000 1.0000
55.5800 127.0000 1.0000
55.6400 137.0000 1.0000
55.7000 106.0000 1.0000
55.7600 114.0000 1.0000
55.8200 108.0000 1.0000
55.8800 81.0000 1.0000
55.9400 102.0000 1.0000
56.0000 102.0000 1.0000
56.0600 160.0000 1.0000
56.1200 120.0000 1.0000
56.1800 136.0000 1.0000
56.2400 116.0000 1.0000
56.3000 106.0000 1.0000
56.3600 98.0000 1.0000
56.4200 85.0000 1.0000
56.4800 81.0000 1.0000
56.5400 79.0000 1.0000
56.6000 65.0000 1.0000
56.6600 72.0000 1.0000
56.7200 51.0000 1.0000
56.7800 71.0000 1.0000
56.8400 60.0000 1.0000
56.9000 55.0000 1.0000
56.9600 53.0000 1.0000
57.0200 48.0000 1.0000
57.0800 51.0000 1.0000
57.1400 49.0000 1.0000
57.2000 51.0000 1.0000
57.2600 31.0000 1.0000
57.3200 45.0000 1.0000
57.3800 50.0000 1.0000
57.4400 48.0000 1.0000
57.5000 45.0000 1.0000
57.5600 44.0000 1.0000
57.6200 55.0000 1.0000
57.6800 44.0000 1.0000
57.7400 45.0000 1.0000
57.8000 42.0000 1.0000
57.8600 46.0000 1.0000
57.9200 40.0000 1.0000
57.9800 38.0000 1.0000
58.0400 41.0000 1.0000
58.1000 67.0000 1.0000
58.1600 56.0000 1.0000
58.2200 74.0000 1.0000
58.2800 103.0000 1.0000
58.3400 130.0000 1.0000
58.4000 216.0000 1.0000
58.4600 294.0000 1.0000
58.5200 313.0000 1.0000
58.5800 328.0000 1.0000
58.6400 330.0000 1.0000
58.7000 365.0000 1.0000
58.7600 317.0000 1.0000
58.8200 328.0000 1.0000
58.8800 267.0000 1.0000
58.9400 227.0000 1.0000
59.0000 198.0000 1.0000
59.0600 143.0000 1.0000
59.1200 98.0000 1.0000
59.1800 86.0000 1.0000
59.2400 65.0000 1.0000
59.3000 53.0000 1.0000
59.3600 40.0000 1.0000
59.4200 35.0000 1.0000
59.4800 46.0000 1.0000
59.5400 44.0000 1.0000
59.6000 53.0000 1.0000
59.6600 41.0000 1.0000
59.7200 49.0000 1.0000
59.7800 43.0000 1.0000
59.8400 43.0000 1.0000
59.9000 39.0000 1.0000
59.9600 41.0000 1.0000
60.0200 44.0000 1.0000
60.0800 46.0000 1.0000
60.1400 57.0000 1.0000
60.2000 35.0000 1.0000
60.2600 44.0000 1.0000
60.3200 50.0000 1.0000
60.3800 57.0000 1.0000
60.4400 47.0000 1.0000
60.5000 47.0000 1.0000
60.5600 43.0000 1.0000
60.6200 46.0000 1.0000
60.6800 40.0000 1.0000
60.7400 48.0000 1.0000
60.8000 41.0000 1.0000
60.8600 33.0000 1.0000
60.9200 37.0000 1.0000
60.9800 34.0000 1.0000
61.0400 26.0000 1.0000
61.1000 44.0000 1.0000
61.1600 35.0000 1.0000
61.2200 42.0000 1.0000
61.2800 32.0000 1.0000
61.3400 45.0000 1.0000
61.4000 48.0000 1.0000
61.4600 44.0000 1.0000
61.5200 40.0000 1.0000
61.5800 46.0000 1.0000
61.6400 45.0000 1.0000
61.7000 38.0000 1.0000
61.7600 48.0000 1.0000
61.8200 43.0000 1.0000
61.8800 36.0000 1.0000
61.9400 41.0000 1.0000
62.0000 45.0000 1.0000
62.0600 33.0000 1.0000
62.1200 47.0000 1.0000
62.1800 43.0000 1.0000
62.2400 58.0000 1.0000
62.3000 55.0000 1.0000
62.3600 56.0000 1.0000
62.4200 40.0000 1.0000
62.4800 49.0000 1.0000
62.5400 40.0000 1.0000
62.6000 53.0000 1.0000
62.6600 48.0000 1.0000
62.7200 40.0000 1.0000
62.7800 34.0000 1.0000
62.8400 41.0000 1.0000
62.9000 54.0000 1.0000
62.9600 37.0000 1.0000
63.0200 51.0000 1.0000
63.0800 33.0000 1.0000
63.1400 45.0000 1.0000
63.2000 38.0000 1.0000
63.2600 43.0000 1.0000
63.3200 47.0000 1.0000
63.3800 38.0000 1.0000
63.4400 49.0000 1.0000
63.5000 33.0000 1.0000
63.5600 38.0000 1.0000
63.6200 29.0000 1.0000
63.6800 36.0000 1.0000
63.7400 42.0000 1.0000
63.8000 38.0000 1.0000
63.8600 36.0000 1.0000
63.9200 53.0000 1.0000
63.9800 34.0000 1.0000
64.0400 50.0000 1.0000
64.1000 46.0000 1.0000
64.1600 27.0000 1.0000
64.2200 44.0000 1.0000
64.2800 55.0000 1.0000
64.3400 27.0000 1.0000
64.4000 56.0000 1.0000
64.4600 43.0000 1.0000
64.5200 41.0000 1.0000
64.5800 52.0000 1.0000
64.6400 41.0000 1.0000
64.7000 48.0000 1.0000
64.7600 47.0000 1.0000
64.8200 53.0000 1.0000
64.8800 61.0000 1.0000
64.9400 89.0000 1.0000
65.0000 146.0000 1.0000
65.0600 148.0000 1.0000
65.1200 138.0000 1.0000
65.1800 134.0000 1.0000
65.2400 142.0000 1.0000
65.3000 118.0000 1.0000
65.3600 118.0000 1.0000
65.4200 93.0000 1.0000
65.4800 115.0000 1.0000
65.5400 133.0000 1.0000
65.6000 144.0000 1.0000
65.6600 141.0000 1.0000
65.7200 128.0000 1.0000
65.7800 117.0000 1.0000
65.8400 120.0000 1.0000
65.9000 137.0000 1.0000
65.9600 93.0000 1.0000
66.0200 77.0000 1.0000
66.0800 79.0000 1.0000
66.1400 60.0000 1.0000
66.2000 69.0000 1.0000
66.2600 74.0000 1.0000
66.3200 78.0000 1.0000
66.3800 103.0000 1.0000
66.4400 111.0000 1.0000
66.5000 125.0000 1.0000
66.5600 136.0000 1.0000
66.6200 122.0000 1.0000
66.6800 102.0000 1.0000
66.7400 70.0000 1.0000
66.8000 76.0000 1.0000
66.8600 73.0000 1.0000
66.9200 63.0000 1.0000
66.9800 56.0000 1.0000
67.0400 67.0000 1.0000
67.1000 55.0000 1.0000
67.1600 58.0000 1.0000
67.2200 52.0000 1.0000
67.2800 48.0000 1.0000
67.3400 37.0000 1.0000
67.4000 45.0000 1.0000
67.4600 46.0000 1.0000
67.5200 46.0000 1.0000
67.5800 48.0000 1.0000
67.6400 49.0000 1.0000
67.7000 53.0000 1.0000
67.7600 57.0000 1.0000
67.8200 56.0000 1.0000
67.8800 51.0000 1.0000
67.9400 59.0000 1.0000
68.0000 59.0000 1.0000
68.0600 43.0000 1.0000
68.1200 41.0000 1.0000
68.1800 41.0000 1.0000
68.2400 42.0000 1.0000
68.3000 42.0000 1.0000
68.3600 36.0000 1.0000
68.4200 37.0000 1.0000
68.4800 52.0000 1.0000
68.5400 44.0000 1.0000
68.6000 45.0000 1.0000
68.6600 47.0000 1.0000
68.7200 44.0000 1.0000
68.7800 55.0000 1.0000
68.8400 39.0000 1.0000
68.9000 42.0000 1.0000
68.9600 42.0000 1.0000
69.0200 45.0000 1.0000
69.0800 48.0000 1.0000
69.1400 39.0000 1.0000
69.2000 41.0000 1.0000
69.2600 46.0000 1.0000
69.3200 30.0000 1.0000
69.3800 45.0000 1.0000
69.4400 38.0000 1.0000
69.5000 29.0000 1.0000
69.5600 39.0000 1.0000
69.6200 43.0000 1.0000
69.6800 56.0000 1.0000
69.7400 45.0000 1.0000
69.8000 39.0000 1.0000
69.8600 50.0000 1.0000
69.9200 42.0000 1.0000
69.9800 51.0000 1.0000
70.0400 41.0000 1.0000
70.1000 38.0000 1.0000
70.1600 39.0000 1.0000
70.2200 54.0000 1.0000
70.2800 66.0000 1.0000
70.3400 61.0000 1.0000
70.4000 82.0000 1.0000
70.4600 83.0000 1.0000
70.5200 91.0000 1.0000
70.5800 106.0000 1.0000
70.6400 110.0000 1.0000
70.7000 101.0000 1.0000
70.7600 121.0000 1.0000
70.8200 112.0000 1.0000
70.8800 112.0000 1.0000
70.9400 86.0000 1.0000
71.0000 93.0000 1.0000
71.0600 63.0000 1.0000
71.1200 81.0000 1.0000
71.1800 66.0000 1.0000
71.2400 44.0000 1.0000
71.3000 52.0000 1.0000
71.3600 47.0000 1.0000
71.4200 55.0000 1.0000
71.4800 53.0000 1.0000
71.5400 44.0000 1.0000
71.6000 37.0000 1.0000
71.6600 60.0000 1.0000
71.7200 29.0000 1.0000
71.7800 36.0000 1.0000
71.8400 44.0000 1.0000
71.9000 40.0000 1.0000
71.9600 53.0000 1.0000
72.0200 47.0000 1.0000
72.0800 57.0000 1.0000
72.1400 57.0000 1.0000
72.2000 50.0000 1.0000
72.2600 55.0000 1.0000
72.3200 51.0000 1.0000
72.3800 44.0000 1.0000
72.4400 59.0000 1.0000
72.5000 42.0000 1.0000
72.5600 38.0000 1.0000
72.6200 41.0000 1.0000
72.6800 32.0000 1.0000
72.7400 36.0000 1.0000
72.8000 42.0000 1.0000
72.8600 47.0000 1.0000
72.9200 46.0000 1.0000
72.9800 43.0000 1.0000
73.0400 45.0000 1.0000
73.1000 50.0000 1.0000
73.1600 40.0000 1.0000
73.2200 47.0000 1.0000
73.2800 40.0000 1.0000
73.3400 37.0000 1.0000
73.4000 28.0000 1.0000
73.4600 43.0000 1.0000
73.5200 51.0000 1.0000
73.5800 41.0000 1.0000
73.6400 40.0000 1.0000
73.7000 41.0000 1.0000
73.7600 49.0000 1.0000
73.8200 42.0000 1.0000
73.8800 39.0000 1.0000
73.9400 33.0000 1.0000
74.0000 37.0000 1.0000
74.0600 40.0000 1.0000
74.1200 35.0000 1.0000
74.1800 40.0000 1.0000
74.2400 42.0000 1.0000
74.3000 46.0000 1.0000
74.3600 28.0000 1.0000
74.4200 42.0000 1.0000
74.4800 49.0000 1.0000
74.5400 31.0000 1.0000
74.6000 37.0000 1.0000
74.6600 35.0000 1.0000
74.7200 48.0000 1.0000
74.7800 39.0000 1.0000
74.8400 62.0000 1.0000
74.9000 50.0000 1.0000
74.9600 35.0000 1.0000
75.0200 27.0000 1.0000
75.0800 38.0000 1.0000
75.1400 56.0000 1.0000
75.2000 53.0000 1.0000
75.2600 87.0000 1.0000
75.3200 93.0000 1.0000
75.3800 106.0000 1.0000
75.4400 119.0000 1.0000
75.5000 127.0000 1.0000
75.5600 118.0000 1.0000
75.6200 130.0000 1.0000
75.6800 147.0000 1.0000
75.7400 101.0000 1.0000
75.8000 97.0000 1.0000
75.8600 74.0000 1.0000
75.9200 66.0000 1.0000
75.9800 60.0000 1.0000
76.0400 68.0000 1.0000
76.1000 68.0000 1.0000
76.1600 64.0000 1.0000
76.2200 71.0000 1.0000
76.2800 53.0000 1.0000
76.3400 68.0000 1.0000
76.4000 66.0000 1.0000
76.4600 90.0000 1.0000
76.5200 109.0000 1.0000
76.5800 123.0000 1.0000
76.6400 131.0000 1.0000
76.7000 96.0000 1.0000
76.7600 112.0000 1.0000
76.8200 89.0000 1.0000
76.8800 111.0000 1.0000
76.9400 78.0000 1.0000
77.0000 57.0000 1.0000
77.0600 71.0000 1.0000
77.1200 54.0000 1.0000
77.1800 65.0000 1.0000
77.2400 63.0000 1.0000
77.3000 58.0000 1.0000
77.3600 54.0000 1.0000
77.4200 58.0000 1.0000
77.4800 53.0000 1.0000
77.5400 73.0000 1.0000
77.6000 62.0000 1.0000
77.6600 53.0000 1.0000
77.7200 60.0000 1.0000
77.7800 53.0000 1.0000
77.8400 47.0000 1.0000
77.9000 66.0000 1.0000
77.9600 55.0000 1.0000
78.0200 48.0000 1.0000
78.0800 45.0000 1.0000
78.1400 32.0000 1.0000
78.2000 52.0000 1.0000
78.2600 56.0000 1.0000
78.3200 37.0000 1.0000
78.3800 30.0000 1.0000
78.4400 43.0000 1.0000
78.5000 43.0000 1.0000
78.5600 44.0000 1.0000
78.6200 48.0000 1.0000
78.6800 46.0000 1.0000
78.7400 57.0000 1.0000
78.8000 50.0000 1.0000
78.8600 59.0000 1.0000
78.9200 80.0000 1.0000
78.9800 83.0000 1.0000
79.0400 85.0000 1.0000
79.1000 97.0000 1.0000
79.1600 97.0000 1.0000
79.2200 98.0000 1.0000
79.2800 89.0000 1.0000
79.3400 93.0000 1.0000
79.4000 97.0000 1.0000
79.4600 88.0000 1.0000
79.5200 98.0000 1.0000
79.5800 96.0000 1.0000
79.6400 80.0000 1.0000
79.7000 80.0000 1.0000
79.7600 64.0000 1.0000
79.8200 59.0000 1.0000
79.8800 67.0000 1.0000
79.9400 56.0000 1.0000
80.0000 54.0000 1.0000
80.0600 72.0000 1.0000
80.1200 61.0000 1.0000
80.1800 70.0000 1.0000
80.2400 84.0000 1.0000
80.3000 65.0000 1.0000
80.3600 95.0000 1.0000
80.4200 106.0000 1.0000
80.4800 108.0000 1.0000
80.5400 102.0000 1.0000
80.6000 111.0000 1.0000
80.6600 88.0000 1.0000
80.7200 112.0000 1.0000
80.7800 110.0000 1.0000
80.8400 91.0000 1.0000
80.9000 94.0000 1.0000
80.9600 98.0000 1.0000
81.0200 88.0000 1.0000
81.0800 94.0000 1.0000
81.1400 68.0000 1.0000
81.2000 83.0000 1.0000
81.2600 65.0000 1.0000
81.3200 62.0000 1.0000
81.3800 58.0000 1.0000
81.4400 49.0000 1.0000
81.5000 63.0000 1.0000
81.5600 63.0000 1.0000
81.6200 57.0000 1.0000
81.6800 55.0000 1.0000
81.7400 48.0000 1.0000
81.8000 40.0000 1.0000
81.8600 39.0000 1.0000
81.9200 51.0000 1.0000
81.9800 54.0000 1.0000
82.0400 43.0000 1.0000
82.1000 42.0000 1.0000
82.1600 47.0000 1.0000
82.2200 38.0000 1.0000
82.2800 40.0000 1.0000
82.3400 46.0000 1.0000
82.4000 47.0000 1.0000
82.4600 44.0000 1.0000
82.5200 38.0000 1.0000
82.5800 38.0000 1.0000
82.6400 44.0000 1.0000
82.7000 43.0000 1.0000
82.7600 41.0000 1.0000
82.8200 48.0000 1.0000
82.8800 44.0000 1.0000
82.9400 50.0000 1.0000
83.0000 42.0000 1.0000
83.0600 40.0000 1.0000
83.1200 46.0000 1.0000
83.1800 51.0000 1.0000
83.2400 50.0000 1.0000
83.3000 37.0000 1.0000
83.3600 49.0000 1.0000
83.4200 45.0000 1.0000
83.4800 39.0000 1.0000
83.5400 37.0000 1.0000
83.6000 52.0000 1.0000
83.6600 41.0000 1.0000
83.7200 48.0000 1.0000
83.7800 56.0000 1.0000
83.8400 58.0000 1.0000
83.9000 43.0000 1.0000
83.9600 49.0000 1.0000
84.0200 44.0000 1.0000
84.0800 44.0000 1.0000
84.1400 52.0000 1.0000
84.2000 59.0000 1.0000
84.2600 86.0000 1.0000
84.3200 80.0000 1.0000
84.3800 97.0000 1.0000
84.4400 99.0000 1.0000
84.5000 99.0000 1.0000
84.5600 121.0000 1.0000
84.6200 121.0000 1.0000
84.6800 120.0000 1.0000
84.7400 102.0000 1.0000
84.8000 113.0000 1.0000
84.8600 102.0000 1.0000
84.9200 115.0000 1.0000
84.9800 89.0000 1.0000
85.0000 100.0000 1.0000
*RAS_INT_END
*RAS_DATA_END